Workbook

Sheet 填寫說明
B2: 表單匯出檔（可修改後匯入）
B3: 本檔由系統「匯出 Excel」產生，欄位、檢查欄與規則和「分項工程表單匯入範本」完全相同。修改後可用表單範本的「匯入檢查項目」或「匯入此分項全部表單」匯入。
B5: 工作表說明
B6: 單元 | C6: 選填。此分項工程的單元編號；沒有單元可整張留白。
B7: 表單 | C7: 每一列＝一張表單的基本資料，「表號」是串接其他工作表的鍵值。「適用單元」決定這張表單要建在哪些單元下。
B8: 檢查項目 | C8: 每一列＝一個檢查項目。單元編號留白＝所有適用單元共用；有填＝只套用在該單元（覆蓋／新增／排除）。
B9: 數值欄位 | C9: 判定類型為「數值」的項目要量測的欄位與檢核條件（下限／上限），規則同上，可依單元設定不同上下限。
B10: 可連結表單 | C10: 自動列出可連結的自主檢查表＝本檔「表單」工作表的自主檢查表＋系統現有的自主檢查表（含空白範本 PDF）；本檔有的以本檔內容為準，「來源」欄標示本檔／系統。「連結表號」「配對自主檢查表號」的下拉選單從這裡選，請勿修改。
B11: 代碼表 | C11: 下拉選單的選項來源與預設階段，請勿修改。
B13: 表單的「適用單元」
B14: 留白 | C14: 表單掛在分項工程下（標案 → 分項工程 → 表單）。
B15: P11、P12 | C15: 列出單元編號（用「、」或「,」分隔），系統會在每個單元下各建一張同表號的表單（標案 → 分項工程 → 單元 → 表單）。
B16: 全部 | C16: 套用到「單元」工作表的所有單元。
B18: 表單的「階段設定」
B19: 留白 | C19: 使用預設階段：施工前、施工中、施工後。
B20: 自訂 | C20: 依填寫順序列出，用「、」分隔，例：挖掘前、挖掘中、挖掘後；階段數可多可少。現場依此順序分頁籤，前一階段完成才能填下一階段。
B21: 檢查項目的「階段」必須是該表單階段設定中的名稱（灰底「階段（展開）」欄會列出可用的階段）。
B23: 同一張表單、不同單元有差異時（共用＋單元覆蓋）
B24: 先把所有單元都一樣的內容寫成「共用列」（單元編號留白），只有不一樣的地方再寫一列「單元列」（填單元編號，淡紫底）：
B25: 覆蓋 | C25: 單元列的 表號＋項次 和共用列相同 → 該單元改用單元列的內容（數值欄位以 表號＋項次＋欄位名稱 比對）。
B26: 新增 | C26: 單元列的項次在共用列沒有 → 該單元多一個專屬項目。
B27: 排除 | C27: 單元列的「排除」填 Y → 該單元不使用這個共用項目／欄位（其餘欄位可留白）。
B28: 例：表5-5 適用全部單元；P12 為公單元，排除第 13 項「端鈑外回填碎石」並新增第 17 項；P11 的鋼筋籠頂高程上下限與共用值不同。
B30: 欄位顏色
C31: 必填欄位（標題有 *）
C32: 選填欄位
C33: 自動帶出／檢查欄位（灰底公式，不用填，匯入時忽略）
C34: 淡紫底＝單元列（只套用在該單元的覆蓋／新增／排除）
B35: 滑鼠移到欄位標題上可看到每個欄位的填寫說明。「檢查」欄出現 ⚠ 表示匯入時會被擋下，✓ 表示沒問題。
B37: 匯入規則
B38: 1. 單元編號在同一分項工程內不可重複（大小寫視為相同）；本檔的單元會加到系統，已存在的略過。
B39: 2. 表號在本檔內不可重複；同一表號可透過「適用單元」建在多個單元下。
B40: 3. 系統已有相同表號（同分項工程、同單元）時：更新該表單；若已有填寫紀錄，另存新版本，舊紀錄保留原內容。
B41: 4. 表單的適用單元必須存在於「單元」工作表或系統已設定的單元。
B42: 5. 檢查項目：同一表號＋單元＋項次不可重複；單元列的單元必須在該表單的適用單元內；排除列必須有對應的共用項次。
B43: 6. 判定類型＝數值：至少要有 1 筆數值欄位；下限、上限需為數字且下限 ≤ 上限，可留白（留白＝只記錄、不檢核）。
B44: 7. 判定類型＝連結表單：連結表號必填，須為「可連結表單」工作表中的表號（本分項系統已有的自主檢查表，含空白範本 PDF，或本檔新增的自主檢查表）。
B45: 8. 引用文件編號若有填，必須存在於系統「參考文件」。
B46: 9. 抽查紀錄表的「配對自主檢查表號」若有填，須為本檔或系統已有的自主檢查表。
B47: 10. 有錯誤的表單整張不匯入（含其檢查項目與欄位），並在匯入預覽列出原因；匯入預覽會顯示每個單元展開後的實際項目。

Sheet 單元
A1: 單元編號 * | B1: 說明

Sheet 表單
A1: 表號 * | B1: 表單名稱 * | C1: 表單類型 * | D1: 適用單元 | E1: 來源依據 | F1: 配對自主檢查表號 | G1: 排序 | H1: 階段設定 | I1: 建立位置（展開） | J1: 階段（展開） | K1: 共用項目數 | L1: 單元差異列數 | M1: 檢查
I2: =IF(A2="","",IF(TRIM(D2)="","（分項工程層）",IF(TRIM(D2)="全部",_xlfn.TEXTJOIN("、",TRUE,單元!$A$2:$A$500),SUBSTITUTE(SUBSTITUTE(SUBSTITUTE(TRIM(D2),"，","、"),",","、")," ","")))) | J2: =IF(A2="","",IF(TRIM(H2)="","施工前、施工中、施工後",SUBSTITUTE(SUBSTITUTE(SUBSTITUTE(TRIM(H2),"，","、"),",","、")," ",""))) | K2: =IF(A2="","",SUMPRODUCT((檢查項目!$A$2:$A$500=A2)*(檢查項目!$B$2:$B$500=""))) | L2: =IF(A2="","",SUMPRODUCT((檢查項目!$A$2:$A$500=A2)*(檢查項目!$B$2:$B$500<>""))+SUMPRODUCT((數值欄位!$A$2:$A$500=A2)*(數值欄位!$B$2:$B$500<>""))) | M2: =IF(A2="","",IF(TRIM(IF(COUNTIF($A$2:$A$500,A2)>1,"⚠ 表號重複 ","")&IF(OR(B2="",C2=""),"⚠ 必填未填 ","")&IF(AND(TRIM(D2)<>"",I2=""),"⚠ 單元工作表沒有單元 ","")&IF(AND(TRIM(D2)<>"",TRIM(D2)<>"全部",I2<>"",SUMPRODUCT((單元!$A$2:$A$500<>"")*ISNUMBER(SEARCH("、"&單元!$A$2:$A$500&"、","、"&I2&"、")))<LEN(I2)-LEN(SUBSTITUTE(I2,"、",""))+1),"⚠ 有單元不存在 ","")&IF(K2+L2=0,"⚠ 尚無檢查項目 ","")&IF(AND(F2<>"",C2<>"抽查紀錄表"),"⚠ 配對表號僅限抽查紀錄表 ","")&IF(AND(F2<>"",C2="抽查紀錄表",COUNTIF(可連結表單!$J$2:$J$501,F2)=0),"⚠ 配對表號不存在（需為本分項的自主檢查表） ",""))="","✓",TRIM(IF(COUNTIF($A$2:$A$500,A2)>1,"⚠ 表號重複 ","")&IF(OR(B2="",C2=""),"⚠ 必填未填 ","")&IF(AND(TRIM(D2)<>"",I2=""),"⚠ 單元工作表沒有單元 ","")&IF(AND(TRIM(D2)<>"",TRIM(D2)<>"全部",I2<>"",SUMPRODUCT((單元!$A$2:$A$500<>"")*ISNUMBER(SEARCH("、"&單元!$A$2:$A$500&"、","、"&I2&"、")))<LEN(I2)-LEN(SUBSTITUTE(I2,"、",""))+1),"⚠ 有單元不存在 ","")&IF(K2+L2=0,"⚠ 尚無檢查項目 ","")&IF(AND(F2<>"",C2<>"抽查紀錄表"),"⚠ 配對表號僅限抽查紀錄表 ","")&IF(AND(F2<>"",C2="抽查紀錄表",COUNTIF(可連結表單!$J$2:$J$501,F2)=0),"⚠ 配對表號不存在（需為本分項的自主檢查表） ",""))))
I3: =IF(A3="","",IF(TRIM(D3)="","（分項工程層）",IF(TRIM(D3)="全部",_xlfn.TEXTJOIN("、",TRUE,單元!$A$2:$A$500),SUBSTITUTE(SUBSTITUTE(SUBSTITUTE(TRIM(D3),"，","、"),",","、")," ","")))) | J3: =IF(A3="","",IF(TRIM(H3)="","施工前、施工中、施工後",SUBSTITUTE(SUBSTITUTE(SUBSTITUTE(TRIM(H3),"，","、"),",","、")," ",""))) | K3: =IF(A3="","",SUMPRODUCT((檢查項目!$A$2:$A$500=A3)*(檢查項目!$B$2:$B$500=""))) | L3: =IF(A3="","",SUMPRODUCT((檢查項目!$A$2:$A$500=A3)*(檢查項目!$B$2:$B$500<>""))+SUMPRODUCT((數值欄位!$A$2:$A$500=A3)*(數值欄位!$B$2:$B$500<>""))) | M3: =IF(A3="","",IF(TRIM(IF(COUNTIF($A$2:$A$500,A3)>1,"⚠ 表號重複 ","")&IF(OR(B3="",C3=""),"⚠ 必填未填 ","")&IF(AND(TRIM(D3)<>"",I3=""),"⚠ 單元工作表沒有單元 ","")&IF(AND(TRIM(D3)<>"",TRIM(D3)<>"全部",I3<>"",SUMPRODUCT((單元!$A$2:$A$500<>"")*ISNUMBER(SEARCH("、"&單元!$A$2:$A$500&"、","、"&I3&"、")))<LEN(I3)-LEN(SUBSTITUTE(I3,"、",""))+1),"⚠ 有單元不存在 ","")&IF(K3+L3=0,"⚠ 尚無檢查項目 ","")&IF(AND(F3<>"",C3<>"抽查紀錄表"),"⚠ 配對表號僅限抽查紀錄表 ","")&IF(AND(F3<>"",C3="抽查紀錄表",COUNTIF(可連結表單!$J$2:$J$501,F3)=0),"⚠ 配對表號不存在（需為本分項的自主檢查表） ",""))="","✓",TRIM(IF(COUNTIF($A$2:$A$500,A3)>1,"⚠ 表號重複 ","")&IF(OR(B3="",C3=""),"⚠ 必填未填 ","")&IF(AND(TRIM(D3)<>"",I3=""),"⚠ 單元工作表沒有單元 ","")&IF(AND(TRIM(D3)<>"",TRIM(D3)<>"全部",I3<>"",SUMPRODUCT((單元!$A$2:$A$500<>"")*ISNUMBER(SEARCH("、"&單元!$A$2:$A$500&"、","、"&I3&"、")))<LEN(I3)-LEN(SUBSTITUTE(I3,"、",""))+1),"⚠ 有單元不存在 ","")&IF(K3+L3=0,"⚠ 尚無檢查項目 ","")&IF(AND(F3<>"",C3<>"抽查紀錄表"),"⚠ 配對表號僅限抽查紀錄表 ","")&IF(AND(F3<>"",C3="抽查紀錄表",COUNTIF(可連結表單!$J$2:$J$501,F3)=0),"⚠ 配對表號不存在（需為本分項的自主檢查表） ",""))))
I4: =IF(A4="","",IF(TRIM(D4)="","（分項工程層）",IF(TRIM(D4)="全部",_xlfn.TEXTJOIN("、",TRUE,單元!$A$2:$A$500),SUBSTITUTE(SUBSTITUTE(SUBSTITUTE(TRIM(D4),"，","、"),",","、")," ","")))) | J4: =IF(A4="","",IF(TRIM(H4)="","施工前、施工中、施工後",SUBSTITUTE(SUBSTITUTE(SUBSTITUTE(TRIM(H4),"，","、"),",","、")," ",""))) | K4: =IF(A4="","",SUMPRODUCT((檢查項目!$A$2:$A$500=A4)*(檢查項目!$B$2:$B$500=""))) | L4: =IF(A4="","",SUMPRODUCT((檢查項目!$A$2:$A$500=A4)*(檢查項目!$B$2:$B$500<>""))+SUMPRODUCT((數值欄位!$A$2:$A$500=A4)*(數值欄位!$B$2:$B$500<>""))) | M4: =IF(A4="","",IF(TRIM(IF(COUNTIF($A$2:$A$500,A4)>1,"⚠ 表號重複 ","")&IF(OR(B4="",C4=""),"⚠ 必填未填 ","")&IF(AND(TRIM(D4)<>"",I4=""),"⚠ 單元工作表沒有單元 ","")&IF(AND(TRIM(D4)<>"",TRIM(D4)<>"全部",I4<>"",SUMPRODUCT((單元!$A$2:$A$500<>"")*ISNUMBER(SEARCH("、"&單元!$A$2:$A$500&"、","、"&I4&"、")))<LEN(I4)-LEN(SUBSTITUTE(I4,"、",""))+1),"⚠ 有單元不存在 ","")&IF(K4+L4=0,"⚠ 尚無檢查項目 ","")&IF(AND(F4<>"",C4<>"抽查紀錄表"),"⚠ 配對表號僅限抽查紀錄表 ","")&IF(AND(F4<>"",C4="抽查紀錄表",COUNTIF(可連結表單!$J$2:$J$501,F4)=0),"⚠ 配對表號不存在（需為本分項的自主檢查表） ",""))="","✓",TRIM(IF(COUNTIF($A$2:$A$500,A4)>1,"⚠ 表號重複 ","")&IF(OR(B4="",C4=""),"⚠ 必填未填 ","")&IF(AND(TRIM(D4)<>"",I4=""),"⚠ 單元工作表沒有單元 ","")&IF(AND(TRIM(D4)<>"",TRIM(D4)<>"全部",I4<>"",SUMPRODUCT((單元!$A$2:$A$500<>"")*ISNUMBER(SEARCH("、"&單元!$A$2:$A$500&"、","、"&I4&"、")))<LEN(I4)-LEN(SUBSTITUTE(I4,"、",""))+1),"⚠ 有單元不存在 ","")&IF(K4+L4=0,"⚠ 尚無檢查項目 ","")&IF(AND(F4<>"",C4<>"抽查紀錄表"),"⚠ 配對表號僅限抽查紀錄表 ","")&IF(AND(F4<>"",C4="抽查紀錄表",COUNTIF(可連結表單!$J$2:$J$501,F4)=0),"⚠ 配對表號不存在（需為本分項的自主檢查表） ",""))))
I5: =IF(A5="","",IF(TRIM(D5)="","（分項工程層）",IF(TRIM(D5)="全部",_xlfn.TEXTJOIN("、",TRUE,單元!$A$2:$A$500),SUBSTITUTE(SUBSTITUTE(SUBSTITUTE(TRIM(D5),"，","、"),",","、")," ","")))) | J5: =IF(A5="","",IF(TRIM(H5)="","施工前、施工中、施工後",SUBSTITUTE(SUBSTITUTE(SUBSTITUTE(TRIM(H5),"，","、"),",","、")," ",""))) | K5: =IF(A5="","",SUMPRODUCT((檢查項目!$A$2:$A$500=A5)*(檢查項目!$B$2:$B$500=""))) | L5: =IF(A5="","",SUMPRODUCT((檢查項目!$A$2:$A$500=A5)*(檢查項目!$B$2:$B$500<>""))+SUMPRODUCT((數值欄位!$A$2:$A$500=A5)*(數值欄位!$B$2:$B$500<>""))) | M5: =IF(A5="","",IF(TRIM(IF(COUNTIF($A$2:$A$500,A5)>1,"⚠ 表號重複 ","")&IF(OR(B5="",C5=""),"⚠ 必填未填 ","")&IF(AND(TRIM(D5)<>"",I5=""),"⚠ 單元工作表沒有單元 ","")&IF(AND(TRIM(D5)<>"",TRIM(D5)<>"全部",I5<>"",SUMPRODUCT((單元!$A$2:$A$500<>"")*ISNUMBER(SEARCH("、"&單元!$A$2:$A$500&"、","、"&I5&"、")))<LEN(I5)-LEN(SUBSTITUTE(I5,"、",""))+1),"⚠ 有單元不存在 ","")&IF(K5+L5=0,"⚠ 尚無檢查項目 ","")&IF(AND(F5<>"",C5<>"抽查紀錄表"),"⚠ 配對表號僅限抽查紀錄表 ","")&IF(AND(F5<>"",C5="抽查紀錄表",COUNTIF(可連結表單!$J$2:$J$501,F5)=0),"⚠ 配對表號不存在（需為本分項的自主檢查表） ",""))="","✓",TRIM(IF(COUNTIF($A$2:$A$500,A5)>1,"⚠ 表號重複 ","")&IF(OR(B5="",C5=""),"⚠ 必填未填 ","")&IF(AND(TRIM(D5)<>"",I5=""),"⚠ 單元工作表沒有單元 ","")&IF(AND(TRIM(D5)<>"",TRIM(D5)<>"全部",I5<>"",SUMPRODUCT((單元!$A$2:$A$500<>"")*ISNUMBER(SEARCH("、"&單元!$A$2:$A$500&"、","、"&I5&"、")))<LEN(I5)-LEN(SUBSTITUTE(I5,"、",""))+1),"⚠ 有單元不存在 ","")&IF(K5+L5=0,"⚠ 尚無檢查項目 ","")&IF(AND(F5<>"",C5<>"抽查紀錄表"),"⚠ 配對表號僅限抽查紀錄表 ","")&IF(AND(F5<>"",C5="抽查紀錄表",COUNTIF(可連結表單!$J$2:$J$501,F5)=0),"⚠ 配對表號不存在（需為本分項的自主檢查表） ",""))))
I6: =IF(A6="","",IF(TRIM(D6)="","（分項工程層）",IF(TRIM(D6)="全部",_xlfn.TEXTJOIN("、",TRUE,單元!$A$2:$A$500),SUBSTITUTE(SUBSTITUTE(SUBSTITUTE(TRIM(D6),"，","、"),",","、")," ","")))) | J6: =IF(A6="","",IF(TRIM(H6)="","施工前、施工中、施工後",SUBSTITUTE(SUBSTITUTE(SUBSTITUTE(TRIM(H6),"，","、"),",","、")," ",""))) | K6: =IF(A6="","",SUMPRODUCT((檢查項目!$A$2:$A$500=A6)*(檢查項目!$B$2:$B$500=""))) | L6: =IF(A6="","",SUMPRODUCT((檢查項目!$A$2:$A$500=A6)*(檢查項目!$B$2:$B$500<>""))+SUMPRODUCT((數值欄位!$A$2:$A$500=A6)*(數值欄位!$B$2:$B$500<>""))) | M6: =IF(A6="","",IF(TRIM(IF(COUNTIF($A$2:$A$500,A6)>1,"⚠ 表號重複 ","")&IF(OR(B6="",C6=""),"⚠ 必填未填 ","")&IF(AND(TRIM(D6)<>"",I6=""),"⚠ 單元工作表沒有單元 ","")&IF(AND(TRIM(D6)<>"",TRIM(D6)<>"全部",I6<>"",SUMPRODUCT((單元!$A$2:$A$500<>"")*ISNUMBER(SEARCH("、"&單元!$A$2:$A$500&"、","、"&I6&"、")))<LEN(I6)-LEN(SUBSTITUTE(I6,"、",""))+1),"⚠ 有單元不存在 ","")&IF(K6+L6=0,"⚠ 尚無檢查項目 ","")&IF(AND(F6<>"",C6<>"抽查紀錄表"),"⚠ 配對表號僅限抽查紀錄表 ","")&IF(AND(F6<>"",C6="抽查紀錄表",COUNTIF(可連結表單!$J$2:$J$501,F6)=0),"⚠ 配對表號不存在（需為本分項的自主檢查表） ",""))="","✓",TRIM(IF(COUNTIF($A$2:$A$500,A6)>1,"⚠ 表號重複 ","")&IF(OR(B6="",C6=""),"⚠ 必填未填 ","")&IF(AND(TRIM(D6)<>"",I6=""),"⚠ 單元工作表沒有單元 ","")&IF(AND(TRIM(D6)<>"",TRIM(D6)<>"全部",I6<>"",SUMPRODUCT((單元!$A$2:$A$500<>"")*ISNUMBER(SEARCH("、"&單元!$A$2:$A$500&"、","、"&I6&"、")))<LEN(I6)-LEN(SUBSTITUTE(I6,"、",""))+1),"⚠ 有單元不存在 ","")&IF(K6+L6=0,"⚠ 尚無檢查項目 ","")&IF(AND(F6<>"",C6<>"抽查紀錄表"),"⚠ 配對表號僅限抽查紀錄表 ","")&IF(AND(F6<>"",C6="抽查紀錄表",COUNTIF(可連結表單!$J$2:$J$501,F6)=0),"⚠ 配對表號不存在（需為本分項的自主檢查表） ",""))))
I7: =IF(A7="","",IF(TRIM(D7)="","（分項工程層）",IF(TRIM(D7)="全部",_xlfn.TEXTJOIN("、",TRUE,單元!$A$2:$A$500),SUBSTITUTE(SUBSTITUTE(SUBSTITUTE(TRIM(D7),"，","、"),",","、")," ","")))) | J7: =IF(A7="","",IF(TRIM(H7)="","施工前、施工中、施工後",SUBSTITUTE(SUBSTITUTE(SUBSTITUTE(TRIM(H7),"，","、"),",","、")," ",""))) | K7: =IF(A7="","",SUMPRODUCT((檢查項目!$A$2:$A$500=A7)*(檢查項目!$B$2:$B$500=""))) | L7: =IF(A7="","",SUMPRODUCT((檢查項目!$A$2:$A$500=A7)*(檢查項目!$B$2:$B$500<>""))+SUMPRODUCT((數值欄位!$A$2:$A$500=A7)*(數值欄位!$B$2:$B$500<>""))) | M7: =IF(A7="","",IF(TRIM(IF(COUNTIF($A$2:$A$500,A7)>1,"⚠ 表號重複 ","")&IF(OR(B7="",C7=""),"⚠ 必填未填 ","")&IF(AND(TRIM(D7)<>"",I7=""),"⚠ 單元工作表沒有單元 ","")&IF(AND(TRIM(D7)<>"",TRIM(D7)<>"全部",I7<>"",SUMPRODUCT((單元!$A$2:$A$500<>"")*ISNUMBER(SEARCH("、"&單元!$A$2:$A$500&"、","、"&I7&"、")))<LEN(I7)-LEN(SUBSTITUTE(I7,"、",""))+1),"⚠ 有單元不存在 ","")&IF(K7+L7=0,"⚠ 尚無檢查項目 ","")&IF(AND(F7<>"",C7<>"抽查紀錄表"),"⚠ 配對表號僅限抽查紀錄表 ","")&IF(AND(F7<>"",C7="抽查紀錄表",COUNTIF(可連結表單!$J$2:$J$501,F7)=0),"⚠ 配對表號不存在（需為本分項的自主檢查表） ",""))="","✓",TRIM(IF(COUNTIF($A$2:$A$500,A7)>1,"⚠ 表號重複 ","")&IF(OR(B7="",C7=""),"⚠ 必填未填 ","")&IF(AND(TRIM(D7)<>"",I7=""),"⚠ 單元工作表沒有單元 ","")&IF(AND(TRIM(D7)<>"",TRIM(D7)<>"全部",I7<>"",SUMPRODUCT((單元!$A$2:$A$500<>"")*ISNUMBER(SEARCH("、"&單元!$A$2:$A$500&"、","、"&I7&"、")))<LEN(I7)-LEN(SUBSTITUTE(I7,"、",""))+1),"⚠ 有單元不存在 ","")&IF(K7+L7=0,"⚠ 尚無檢查項目 ","")&IF(AND(F7<>"",C7<>"抽查紀錄表"),"⚠ 配對表號僅限抽查紀錄表 ","")&IF(AND(F7<>"",C7="抽查紀錄表",COUNTIF(可連結表單!$J$2:$J$501,F7)=0),"⚠ 配對表號不存在（需為本分項的自主檢查表） ",""))))
I8: =IF(A8="","",IF(TRIM(D8)="","（分項工程層）",IF(TRIM(D8)="全部",_xlfn.TEXTJOIN("、",TRUE,單元!$A$2:$A$500),SUBSTITUTE(SUBSTITUTE(SUBSTITUTE(TRIM(D8),"，","、"),",","、")," ","")))) | J8: =IF(A8="","",IF(TRIM(H8)="","施工前、施工中、施工後",SUBSTITUTE(SUBSTITUTE(SUBSTITUTE(TRIM(H8),"，","、"),",","、")," ",""))) | K8: =IF(A8="","",SUMPRODUCT((檢查項目!$A$2:$A$500=A8)*(檢查項目!$B$2:$B$500=""))) | L8: =IF(A8="","",SUMPRODUCT((檢查項目!$A$2:$A$500=A8)*(檢查項目!$B$2:$B$500<>""))+SUMPRODUCT((數值欄位!$A$2:$A$500=A8)*(數值欄位!$B$2:$B$500<>""))) | M8: =IF(A8="","",IF(TRIM(IF(COUNTIF($A$2:$A$500,A8)>1,"⚠ 表號重複 ","")&IF(OR(B8="",C8=""),"⚠ 必填未填 ","")&IF(AND(TRIM(D8)<>"",I8=""),"⚠ 單元工作表沒有單元 ","")&IF(AND(TRIM(D8)<>"",TRIM(D8)<>"全部",I8<>"",SUMPRODUCT((單元!$A$2:$A$500<>"")*ISNUMBER(SEARCH("、"&單元!$A$2:$A$500&"、","、"&I8&"、")))<LEN(I8)-LEN(SUBSTITUTE(I8,"、",""))+1),"⚠ 有單元不存在 ","")&IF(K8+L8=0,"⚠ 尚無檢查項目 ","")&IF(AND(F8<>"",C8<>"抽查紀錄表"),"⚠ 配對表號僅限抽查紀錄表 ","")&IF(AND(F8<>"",C8="抽查紀錄表",COUNTIF(可連結表單!$J$2:$J$501,F8)=0),"⚠ 配對表號不存在（需為本分項的自主檢查表） ",""))="","✓",TRIM(IF(COUNTIF($A$2:$A$500,A8)>1,"⚠ 表號重複 ","")&IF(OR(B8="",C8=""),"⚠ 必填未填 ","")&IF(AND(TRIM(D8)<>"",I8=""),"⚠ 單元工作表沒有單元 ","")&IF(AND(TRIM(D8)<>"",TRIM(D8)<>"全部",I8<>"",SUMPRODUCT((單元!$A$2:$A$500<>"")*ISNUMBER(SEARCH("、"&單元!$A$2:$A$500&"、","、"&I8&"、")))<LEN(I8)-LEN(SUBSTITUTE(I8,"、",""))+1),"⚠ 有單元不存在 ","")&IF(K8+L8=0,"⚠ 尚無檢查項目 ","")&IF(AND(F8<>"",C8<>"抽查紀錄表"),"⚠ 配對表號僅限抽查紀錄表 ","")&IF(AND(F8<>"",C8="抽查紀錄表",COUNTIF(可連結表單!$J$2:$J$501,F8)=0),"⚠ 配對表號不存在（需為本分項的自主檢查表） ",""))))
I9: =IF(A9="","",IF(TRIM(D9)="","（分項工程層）",IF(TRIM(D9)="全部",_xlfn.TEXTJOIN("、",TRUE,單元!$A$2:$A$500),SUBSTITUTE(SUBSTITUTE(SUBSTITUTE(TRIM(D9),"，","、"),",","、")," ","")))) | J9: =IF(A9="","",IF(TRIM(H9)="","施工前、施工中、施工後",SUBSTITUTE(SUBSTITUTE(SUBSTITUTE(TRIM(H9),"，","、"),",","、")," ",""))) | K9: =IF(A9="","",SUMPRODUCT((檢查項目!$A$2:$A$500=A9)*(檢查項目!$B$2:$B$500=""))) | L9: =IF(A9="","",SUMPRODUCT((檢查項目!$A$2:$A$500=A9)*(檢查項目!$B$2:$B$500<>""))+SUMPRODUCT((數值欄位!$A$2:$A$500=A9)*(數值欄位!$B$2:$B$500<>""))) | M9: =IF(A9="","",IF(TRIM(IF(COUNTIF($A$2:$A$500,A9)>1,"⚠ 表號重複 ","")&IF(OR(B9="",C9=""),"⚠ 必填未填 ","")&IF(AND(TRIM(D9)<>"",I9=""),"⚠ 單元工作表沒有單元 ","")&IF(AND(TRIM(D9)<>"",TRIM(D9)<>"全部",I9<>"",SUMPRODUCT((單元!$A$2:$A$500<>"")*ISNUMBER(SEARCH("、"&單元!$A$2:$A$500&"、","、"&I9&"、")))<LEN(I9)-LEN(SUBSTITUTE(I9,"、",""))+1),"⚠ 有單元不存在 ","")&IF(K9+L9=0,"⚠ 尚無檢查項目 ","")&IF(AND(F9<>"",C9<>"抽查紀錄表"),"⚠ 配對表號僅限抽查紀錄表 ","")&IF(AND(F9<>"",C9="抽查紀錄表",COUNTIF(可連結表單!$J$2:$J$501,F9)=0),"⚠ 配對表號不存在（需為本分項的自主檢查表） ",""))="","✓",TRIM(IF(COUNTIF($A$2:$A$500,A9)>1,"⚠ 表號重複 ","")&IF(OR(B9="",C9=""),"⚠ 必填未填 ","")&IF(AND(TRIM(D9)<>"",I9=""),"⚠ 單元工作表沒有單元 ","")&IF(AND(TRIM(D9)<>"",TRIM(D9)<>"全部",I9<>"",SUMPRODUCT((單元!$A$2:$A$500<>"")*ISNUMBER(SEARCH("、"&單元!$A$2:$A$500&"、","、"&I9&"、")))<LEN(I9)-LEN(SUBSTITUTE(I9,"、",""))+1),"⚠ 有單元不存在 ","")&IF(K9+L9=0,"⚠ 尚無檢查項目 ","")&IF(AND(F9<>"",C9<>"抽查紀錄表"),"⚠ 配對表號僅限抽查紀錄表 ","")&IF(AND(F9<>"",C9="抽查紀錄表",COUNTIF(可連結表單!$J$2:$J$501,F9)=0),"⚠ 配對表號不存在（需為本分項的自主檢查表） ",""))))
I10: =IF(A10="","",IF(TRIM(D10)="","（分項工程層）",IF(TRIM(D10)="全部",_xlfn.TEXTJOIN("、",TRUE,單元!$A$2:$A$500),SUBSTITUTE(SUBSTITUTE(SUBSTITUTE(TRIM(D10),"，","、"),",","、")," ","")))) | J10: =IF(A10="","",IF(TRIM(H10)="","施工前、施工中、施工後",SUBSTITUTE(SUBSTITUTE(SUBSTITUTE(TRIM(H10),"，","、"),",","、")," ",""))) | K10: =IF(A10="","",SUMPRODUCT((檢查項目!$A$2:$A$500=A10)*(檢查項目!$B$2:$B$500=""))) | L10: =IF(A10="","",SUMPRODUCT((檢查項目!$A$2:$A$500=A10)*(檢查項目!$B$2:$B$500<>""))+SUMPRODUCT((數值欄位!$A$2:$A$500=A10)*(數值欄位!$B$2:$B$500<>""))) | M10: =IF(A10="","",IF(TRIM(IF(COUNTIF($A$2:$A$500,A10)>1,"⚠ 表號重複 ","")&IF(OR(B10="",C10=""),"⚠ 必填未填 ","")&IF(AND(TRIM(D10)<>"",I10=""),"⚠ 單元工作表沒有單元 ","")&IF(AND(TRIM(D10)<>"",TRIM(D10)<>"全部",I10<>"",SUMPRODUCT((單元!$A$2:$A$500<>"")*ISNUMBER(SEARCH("、"&單元!$A$2:$A$500&"、","、"&I10&"、")))<LEN(I10)-LEN(SUBSTITUTE(I10,"、",""))+1),"⚠ 有單元不存在 ","")&IF(K10+L10=0,"⚠ 尚無檢查項目 ","")&IF(AND(F10<>"",C10<>"抽查紀錄表"),"⚠ 配對表號僅限抽查紀錄表 ","")&IF(AND(F10<>"",C10="抽查紀錄表",COUNTIF(可連結表單!$J$2:$J$501,F10)=0),"⚠ 配對表號不存在（需為本分項的自主檢查表） ",""))="","✓",TRIM(IF(COUNTIF($A$2:$A$500,A10)>1,"⚠ 表號重複 ","")&IF(OR(B10="",C10=""),"⚠ 必填未填 ","")&IF(AND(TRIM(D10)<>"",I10=""),"⚠ 單元工作表沒有單元 ","")&IF(AND(TRIM(D10)<>"",TRIM(D10)<>"全部",I10<>"",SUMPRODUCT((單元!$A$2:$A$500<>"")*ISNUMBER(SEARCH("、"&單元!$A$2:$A$500&"、","、"&I10&"、")))<LEN(I10)-LEN(SUBSTITUTE(I10,"、",""))+1),"⚠ 有單元不存在 ","")&IF(K10+L10=0,"⚠ 尚無檢查項目 ","")&IF(AND(F10<>"",C10<>"抽查紀錄表"),"⚠ 配對表號僅限抽查紀錄表 ","")&IF(AND(F10<>"",C10="抽查紀錄表",COUNTIF(可連結表單!$J$2:$J$501,F10)=0),"⚠ 配對表號不存在（需為本分項的自主檢查表） ",""))))
I11: =IF(A11="","",IF(TRIM(D11)="","（分項工程層）",IF(TRIM(D11)="全部",_xlfn.TEXTJOIN("、",TRUE,單元!$A$2:$A$500),SUBSTITUTE(SUBSTITUTE(SUBSTITUTE(TRIM(D11),"，","、"),",","、")," ","")))) | J11: =IF(A11="","",IF(TRIM(H11)="","施工前、施工中、施工後",SUBSTITUTE(SUBSTITUTE(SUBSTITUTE(TRIM(H11),"，","、"),",","、")," ",""))) | K11: =IF(A11="","",SUMPRODUCT((檢查項目!$A$2:$A$500=A11)*(檢查項目!$B$2:$B$500=""))) | L11: =IF(A11="","",SUMPRODUCT((檢查項目!$A$2:$A$500=A11)*(檢查項目!$B$2:$B$500<>""))+SUMPRODUCT((數值欄位!$A$2:$A$500=A11)*(數值欄位!$B$2:$B$500<>""))) | M11: =IF(A11="","",IF(TRIM(IF(COUNTIF($A$2:$A$500,A11)>1,"⚠ 表號重複 ","")&IF(OR(B11="",C11=""),"⚠ 必填未填 ","")&IF(AND(TRIM(D11)<>"",I11=""),"⚠ 單元工作表沒有單元 ","")&IF(AND(TRIM(D11)<>"",TRIM(D11)<>"全部",I11<>"",SUMPRODUCT((單元!$A$2:$A$500<>"")*ISNUMBER(SEARCH("、"&單元!$A$2:$A$500&"、","、"&I11&"、")))<LEN(I11)-LEN(SUBSTITUTE(I11,"、",""))+1),"⚠ 有單元不存在 ","")&IF(K11+L11=0,"⚠ 尚無檢查項目 ","")&IF(AND(F11<>"",C11<>"抽查紀錄表"),"⚠ 配對表號僅限抽查紀錄表 ","")&IF(AND(F11<>"",C11="抽查紀錄表",COUNTIF(可連結表單!$J$2:$J$501,F11)=0),"⚠ 配對表號不存在（需為本分項的自主檢查表） ",""))="","✓",TRIM(IF(COUNTIF($A$2:$A$500,A11)>1,"⚠ 表號重複 ","")&IF(OR(B11="",C11=""),"⚠ 必填未填 ","")&IF(AND(TRIM(D11)<>"",I11=""),"⚠ 單元工作表沒有單元 ","")&IF(AND(TRIM(D11)<>"",TRIM(D11)<>"全部",I11<>"",SUMPRODUCT((單元!$A$2:$A$500<>"")*ISNUMBER(SEARCH("、"&單元!$A$2:$A$500&"、","、"&I11&"、")))<LEN(I11)-LEN(SUBSTITUTE(I11,"、",""))+1),"⚠ 有單元不存在 ","")&IF(K11+L11=0,"⚠ 尚無檢查項目 ","")&IF(AND(F11<>"",C11<>"抽查紀錄表"),"⚠ 配對表號僅限抽查紀錄表 ","")&IF(AND(F11<>"",C11="抽查紀錄表",COUNTIF(可連結表單!$J$2:$J$501,F11)=0),"⚠ 配對表號不存在（需為本分項的自主檢查表） ",""))))
I12: =IF(A12="","",IF(TRIM(D12)="","（分項工程層）",IF(TRIM(D12)="全部",_xlfn.TEXTJOIN("、",TRUE,單元!$A$2:$A$500),SUBSTITUTE(SUBSTITUTE(SUBSTITUTE(TRIM(D12),"，","、"),",","、")," ","")))) | J12: =IF(A12="","",IF(TRIM(H12)="","施工前、施工中、施工後",SUBSTITUTE(SUBSTITUTE(SUBSTITUTE(TRIM(H12),"，","、"),",","、")," ",""))) | K12: =IF(A12="","",SUMPRODUCT((檢查項目!$A$2:$A$500=A12)*(檢查項目!$B$2:$B$500=""))) | L12: =IF(A12="","",SUMPRODUCT((檢查項目!$A$2:$A$500=A12)*(檢查項目!$B$2:$B$500<>""))+SUMPRODUCT((數值欄位!$A$2:$A$500=A12)*(數值欄位!$B$2:$B$500<>""))) | M12: =IF(A12="","",IF(TRIM(IF(COUNTIF($A$2:$A$500,A12)>1,"⚠ 表號重複 ","")&IF(OR(B12="",C12=""),"⚠ 必填未填 ","")&IF(AND(TRIM(D12)<>"",I12=""),"⚠ 單元工作表沒有單元 ","")&IF(AND(TRIM(D12)<>"",TRIM(D12)<>"全部",I12<>"",SUMPRODUCT((單元!$A$2:$A$500<>"")*ISNUMBER(SEARCH("、"&單元!$A$2:$A$500&"、","、"&I12&"、")))<LEN(I12)-LEN(SUBSTITUTE(I12,"、",""))+1),"⚠ 有單元不存在 ","")&IF(K12+L12=0,"⚠ 尚無檢查項目 ","")&IF(AND(F12<>"",C12<>"抽查紀錄表"),"⚠ 配對表號僅限抽查紀錄表 ","")&IF(AND(F12<>"",C12="抽查紀錄表",COUNTIF(可連結表單!$J$2:$J$501,F12)=0),"⚠ 配對表號不存在（需為本分項的自主檢查表） ",""))="","✓",TRIM(IF(COUNTIF($A$2:$A$500,A12)>1,"⚠ 表號重複 ","")&IF(OR(B12="",C12=""),"⚠ 必填未填 ","")&IF(AND(TRIM(D12)<>"",I12=""),"⚠ 單元工作表沒有單元 ","")&IF(AND(TRIM(D12)<>"",TRIM(D12)<>"全部",I12<>"",SUMPRODUCT((單元!$A$2:$A$500<>"")*ISNUMBER(SEARCH("、"&單元!$A$2:$A$500&"、","、"&I12&"、")))<LEN(I12)-LEN(SUBSTITUTE(I12,"、",""))+1),"⚠ 有單元不存在 ","")&IF(K12+L12=0,"⚠ 尚無檢查項目 ","")&IF(AND(F12<>"",C12<>"抽查紀錄表"),"⚠ 配對表號僅限抽查紀錄表 ","")&IF(AND(F12<>"",C12="抽查紀錄表",COUNTIF(可連結表單!$J$2:$J$501,F12)=0),"⚠ 配對表號不存在（需為本分項的自主檢查表） ",""))))
I13: =IF(A13="","",IF(TRIM(D13)="","（分項工程層）",IF(TRIM(D13)="全部",_xlfn.TEXTJOIN("、",TRUE,單元!$A$2:$A$500),SUBSTITUTE(SUBSTITUTE(SUBSTITUTE(TRIM(D13),"，","、"),",","、")," ","")))) | J13: =IF(A13="","",IF(TRIM(H13)="","施工前、施工中、施工後",SUBSTITUTE(SUBSTITUTE(SUBSTITUTE(TRIM(H13),"，","、"),",","、")," ",""))) | K13: =IF(A13="","",SUMPRODUCT((檢查項目!$A$2:$A$500=A13)*(檢查項目!$B$2:$B$500=""))) | L13: =IF(A13="","",SUMPRODUCT((檢查項目!$A$2:$A$500=A13)*(檢查項目!$B$2:$B$500<>""))+SUMPRODUCT((數值欄位!$A$2:$A$500=A13)*(數值欄位!$B$2:$B$500<>""))) | M13: =IF(A13="","",IF(TRIM(IF(COUNTIF($A$2:$A$500,A13)>1,"⚠ 表號重複 ","")&IF(OR(B13="",C13=""),"⚠ 必填未填 ","")&IF(AND(TRIM(D13)<>"",I13=""),"⚠ 單元工作表沒有單元 ","")&IF(AND(TRIM(D13)<>"",TRIM(D13)<>"全部",I13<>"",SUMPRODUCT((單元!$A$2:$A$500<>"")*ISNUMBER(SEARCH("、"&單元!$A$2:$A$500&"、","、"&I13&"、")))<LEN(I13)-LEN(SUBSTITUTE(I13,"、",""))+1),"⚠ 有單元不存在 ","")&IF(K13+L13=0,"⚠ 尚無檢查項目 ","")&IF(AND(F13<>"",C13<>"抽查紀錄表"),"⚠ 配對表號僅限抽查紀錄表 ","")&IF(AND(F13<>"",C13="抽查紀錄表",COUNTIF(可連結表單!$J$2:$J$501,F13)=0),"⚠ 配對表號不存在（需為本分項的自主檢查表） ",""))="","✓",TRIM(IF(COUNTIF($A$2:$A$500,A13)>1,"⚠ 表號重複 ","")&IF(OR(B13="",C13=""),"⚠ 必填未填 ","")&IF(AND(TRIM(D13)<>"",I13=""),"⚠ 單元工作表沒有單元 ","")&IF(AND(TRIM(D13)<>"",TRIM(D13)<>"全部",I13<>"",SUMPRODUCT((單元!$A$2:$A$500<>"")*ISNUMBER(SEARCH("、"&單元!$A$2:$A$500&"、","、"&I13&"、")))<LEN(I13)-LEN(SUBSTITUTE(I13,"、",""))+1),"⚠ 有單元不存在 ","")&IF(K13+L13=0,"⚠ 尚無檢查項目 ","")&IF(AND(F13<>"",C13<>"抽查紀錄表"),"⚠ 配對表號僅限抽查紀錄表 ","")&IF(AND(F13<>"",C13="抽查紀錄表",COUNTIF(可連結表單!$J$2:$J$501,F13)=0),"⚠ 配對表號不存在（需為本分項的自主檢查表） ",""))))
... I300: =IF(A300="","",IF(TRIM(D300)="","（分項工程層）",IF(TRIM(D300)="全部",_xlfn.TEXTJOIN("、",TRUE,單元!$A$2:$A$500),SUBSTITUTE(SUBSTITUTE(SUBSTITUTE(TRIM(D300),"，","、"),",","、")," ","")))) | J300: =IF(A300="","",IF(TRIM(H300)="","施工前、施工中、施工後",SUBSTITUTE(SUBSTITUTE(SUBSTITUTE(TRIM(H300),"，","、"),",","、")," ",""))) | K300: =IF(A300="","",SUMPRODUCT((檢查項目!$A$2:$A$500=A300)*(檢查項目!$B$2:$B$500=""))) | L300: =IF(A300="","",SUMPRODUCT((檢查項目!$A$2:$A$500=A300)*(檢查項目!$B$2:$B$500<>""))+SUMPRODUCT((數值欄位!$A$2:$A$500=A300)*(數值欄位!$B$2:$B$500<>""))) | M300: =IF(A300="","",IF(TRIM(IF(COUNTIF($A$2:$A$500,A300)>1,"⚠ 表號重複 ","")&IF(OR(B300="",C300=""),"⚠ 必填未填 ","")&IF(AND(TRIM(D300)<>"",I300=""),"⚠ 單元工作表沒有單元 ","")&IF(AND(TRIM(D300)<>"",TRIM(D300)<>"全部",I300<>"",SUMPRODUCT((單元!$A$2:$A$500<>"")*ISNUMBER(SEARCH("、"&單元!$A$2:$A$500&"、","、"&I300&"、")))<LEN(I300)-LEN(SUBSTITUTE(I300,"、",""))+1),"⚠ 有單元不存在 ","")&IF(K300+L300=0,"⚠ 尚無檢查項目 ","")&IF(AND(F300<>"",C300<>"抽查紀錄表"),"⚠ 配對表號僅限抽查紀錄表 ","")&IF(AND(F300<>"",C300="抽查紀錄表",COUNTIF(可連結表單!$J$2:$J$501,F300)=0),"⚠ 配對表號不存在（需為本分項的自主檢查表） ",""))="","✓",TRIM(IF(COUNTIF($A$2:$A$500,A300)>1,"⚠ 表號重複 ","")&IF(OR(B300="",C300=""),"⚠ 必填未填 ","")&IF(AND(TRIM(D300)<>"",I300=""),"⚠ 單元工作表沒有單元 ","")&IF(AND(TRIM(D300)<>"",TRIM(D300)<>"全部",I300<>"",SUMPRODUCT((單元!$A$2:$A$500<>"")*ISNUMBER(SEARCH("、"&單元!$A$2:$A$500&"、","、"&I300&"、")))<LEN(I300)-LEN(SUBSTITUTE(I300,"、",""))+1),"⚠ 有單元不存在 ","")&IF(K300+L300=0,"⚠ 尚無檢查項目 ","")&IF(AND(F300<>"",C300<>"抽查紀錄表"),"⚠ 配對表號僅限抽查紀錄表 ","")&IF(AND(F300<>"",C300="抽查紀錄表",COUNTIF(可連結表單!$J$2:$J$501,F300)=0),"⚠ 配對表號不存在（需為本分項的自主檢查表） ",""))))

Sheet 檢查項目
A1: 表號 * | B1: 單元編號 | C1: 項次 * | D1: 階段 * | E1: 檢查項目 * | F1: 檢查標準 | G1: 判定類型 * | H1: 停留點 | I1: 必拍照 | J1: 引用文件編號 | K1: 連結表號 | L1: 排除 | M1: 套用方式 | N1: 數值欄位數 | O1: 檢查
M2: =IF(A2="","",IF(B2="","共用",IF(L2="Y","排除（"&B2&"）",IF(SUMPRODUCT(($A$2:$A$500=A2)*($C$2:$C$500=C2)*($B$2:$B$500=""))>0,"覆蓋共用（"&B2&"）","單元新增（"&B2&"）")))) | N2: =IF(A2="","",COUNTIFS(數值欄位!$A$2:$A$500,A2,數值欄位!$C$2:$C$500,C2)) | O2: =IF(A2="","",IF(TRIM(IF(COUNTIF(表單!$A$2:$A$500,A2)=0,"⚠ 表號不存在 ","")&IF(SUMPRODUCT(($A$2:$A$500=A2)*($B$2:$B$500=B2)*($C$2:$C$500=C2))>1,"⚠ 項次重複 ","")&IF(AND(B2<>"",COUNTIF(表單!$A$2:$A$500,A2)>0,NOT(ISNUMBER(SEARCH("、"&B2&"、","、"&IFERROR(INDEX(表單!$I$2:$I$500,MATCH(A2,表單!$A$2:$A$500,0)),"")&"、")))),"⚠ 單元不在適用單元內 ","")&IF(AND(L2="Y",B2=""),"⚠ 排除只能用在單元列 ","")&IF(AND(L2="Y",B2<>"",SUMPRODUCT(($A$2:$A$500=A2)*($C$2:$C$500=C2)*($B$2:$B$500=""))=0),"⚠ 排除需對應共用項次 ","")&IF(AND(L2<>"Y",OR(D2="",E2="",G2="")),"⚠ 必填未填 ","")&IF(AND(L2<>"Y",D2<>"",COUNTIF(表單!$A$2:$A$500,A2)>0,NOT(ISNUMBER(SEARCH("、"&D2&"、","、"&IFERROR(INDEX(表單!$J$2:$J$500,MATCH(A2,表單!$A$2:$A$500,0)),"")&"、")))),"⚠ 階段不在此表單的階段設定內 ","")&IF(AND(L2<>"Y",G2="數值",N2=0),"⚠ 數值需設定欄位 ","")&IF(AND(L2<>"Y",G2="連結表單",K2=""),"⚠ 缺連結表號 ","")&IF(AND(K2<>"",COUNTIF(可連結表單!$J$2:$J$501,K2)=0),"⚠ 連結表號不存在（需為本分項的自主檢查表） ",""))="","✓",TRIM(IF(COUNTIF(表單!$A$2:$A$500,A2)=0,"⚠ 表號不存在 ","")&IF(SUMPRODUCT(($A$2:$A$500=A2)*($B$2:$B$500=B2)*($C$2:$C$500=C2))>1,"⚠ 項次重複 ","")&IF(AND(B2<>"",COUNTIF(表單!$A$2:$A$500,A2)>0,NOT(ISNUMBER(SEARCH("、"&B2&"、","、"&IFERROR(INDEX(表單!$I$2:$I$500,MATCH(A2,表單!$A$2:$A$500,0)),"")&"、")))),"⚠ 單元不在適用單元內 ","")&IF(AND(L2="Y",B2=""),"⚠ 排除只能用在單元列 ","")&IF(AND(L2="Y",B2<>"",SUMPRODUCT(($A$2:$A$500=A2)*($C$2:$C$500=C2)*($B$2:$B$500=""))=0),"⚠ 排除需對應共用項次 ","")&IF(AND(L2<>"Y",OR(D2="",E2="",G2="")),"⚠ 必填未填 ","")&IF(AND(L2<>"Y",D2<>"",COUNTIF(表單!$A$2:$A$500,A2)>0,NOT(ISNUMBER(SEARCH("、"&D2&"、","、"&IFERROR(INDEX(表單!$J$2:$J$500,MATCH(A2,表單!$A$2:$A$500,0)),"")&"、")))),"⚠ 階段不在此表單的階段設定內 ","")&IF(AND(L2<>"Y",G2="數值",N2=0),"⚠ 數值需設定欄位 ","")&IF(AND(L2<>"Y",G2="連結表單",K2=""),"⚠ 缺連結表號 ","")&IF(AND(K2<>"",COUNTIF(可連結表單!$J$2:$J$501,K2)=0),"⚠ 連結表號不存在（需為本分項的自主檢查表） ",""))))
M3: =IF(A3="","",IF(B3="","共用",IF(L3="Y","排除（"&B3&"）",IF(SUMPRODUCT(($A$2:$A$500=A3)*($C$2:$C$500=C3)*($B$2:$B$500=""))>0,"覆蓋共用（"&B3&"）","單元新增（"&B3&"）")))) | N3: =IF(A3="","",COUNTIFS(數值欄位!$A$2:$A$500,A3,數值欄位!$C$2:$C$500,C3)) | O3: =IF(A3="","",IF(TRIM(IF(COUNTIF(表單!$A$2:$A$500,A3)=0,"⚠ 表號不存在 ","")&IF(SUMPRODUCT(($A$2:$A$500=A3)*($B$2:$B$500=B3)*($C$2:$C$500=C3))>1,"⚠ 項次重複 ","")&IF(AND(B3<>"",COUNTIF(表單!$A$2:$A$500,A3)>0,NOT(ISNUMBER(SEARCH("、"&B3&"、","、"&IFERROR(INDEX(表單!$I$2:$I$500,MATCH(A3,表單!$A$2:$A$500,0)),"")&"、")))),"⚠ 單元不在適用單元內 ","")&IF(AND(L3="Y",B3=""),"⚠ 排除只能用在單元列 ","")&IF(AND(L3="Y",B3<>"",SUMPRODUCT(($A$2:$A$500=A3)*($C$2:$C$500=C3)*($B$2:$B$500=""))=0),"⚠ 排除需對應共用項次 ","")&IF(AND(L3<>"Y",OR(D3="",E3="",G3="")),"⚠ 必填未填 ","")&IF(AND(L3<>"Y",D3<>"",COUNTIF(表單!$A$2:$A$500,A3)>0,NOT(ISNUMBER(SEARCH("、"&D3&"、","、"&IFERROR(INDEX(表單!$J$2:$J$500,MATCH(A3,表單!$A$2:$A$500,0)),"")&"、")))),"⚠ 階段不在此表單的階段設定內 ","")&IF(AND(L3<>"Y",G3="數值",N3=0),"⚠ 數值需設定欄位 ","")&IF(AND(L3<>"Y",G3="連結表單",K3=""),"⚠ 缺連結表號 ","")&IF(AND(K3<>"",COUNTIF(可連結表單!$J$2:$J$501,K3)=0),"⚠ 連結表號不存在（需為本分項的自主檢查表） ",""))="","✓",TRIM(IF(COUNTIF(表單!$A$2:$A$500,A3)=0,"⚠ 表號不存在 ","")&IF(SUMPRODUCT(($A$2:$A$500=A3)*($B$2:$B$500=B3)*($C$2:$C$500=C3))>1,"⚠ 項次重複 ","")&IF(AND(B3<>"",COUNTIF(表單!$A$2:$A$500,A3)>0,NOT(ISNUMBER(SEARCH("、"&B3&"、","、"&IFERROR(INDEX(表單!$I$2:$I$500,MATCH(A3,表單!$A$2:$A$500,0)),"")&"、")))),"⚠ 單元不在適用單元內 ","")&IF(AND(L3="Y",B3=""),"⚠ 排除只能用在單元列 ","")&IF(AND(L3="Y",B3<>"",SUMPRODUCT(($A$2:$A$500=A3)*($C$2:$C$500=C3)*($B$2:$B$500=""))=0),"⚠ 排除需對應共用項次 ","")&IF(AND(L3<>"Y",OR(D3="",E3="",G3="")),"⚠ 必填未填 ","")&IF(AND(L3<>"Y",D3<>"",COUNTIF(表單!$A$2:$A$500,A3)>0,NOT(ISNUMBER(SEARCH("、"&D3&"、","、"&IFERROR(INDEX(表單!$J$2:$J$500,MATCH(A3,表單!$A$2:$A$500,0)),"")&"、")))),"⚠ 階段不在此表單的階段設定內 ","")&IF(AND(L3<>"Y",G3="數值",N3=0),"⚠ 數值需設定欄位 ","")&IF(AND(L3<>"Y",G3="連結表單",K3=""),"⚠ 缺連結表號 ","")&IF(AND(K3<>"",COUNTIF(可連結表單!$J$2:$J$501,K3)=0),"⚠ 連結表號不存在（需為本分項的自主檢查表） ",""))))
M4: =IF(A4="","",IF(B4="","共用",IF(L4="Y","排除（"&B4&"）",IF(SUMPRODUCT(($A$2:$A$500=A4)*($C$2:$C$500=C4)*($B$2:$B$500=""))>0,"覆蓋共用（"&B4&"）","單元新增（"&B4&"）")))) | N4: =IF(A4="","",COUNTIFS(數值欄位!$A$2:$A$500,A4,數值欄位!$C$2:$C$500,C4)) | O4: =IF(A4="","",IF(TRIM(IF(COUNTIF(表單!$A$2:$A$500,A4)=0,"⚠ 表號不存在 ","")&IF(SUMPRODUCT(($A$2:$A$500=A4)*($B$2:$B$500=B4)*($C$2:$C$500=C4))>1,"⚠ 項次重複 ","")&IF(AND(B4<>"",COUNTIF(表單!$A$2:$A$500,A4)>0,NOT(ISNUMBER(SEARCH("、"&B4&"、","、"&IFERROR(INDEX(表單!$I$2:$I$500,MATCH(A4,表單!$A$2:$A$500,0)),"")&"、")))),"⚠ 單元不在適用單元內 ","")&IF(AND(L4="Y",B4=""),"⚠ 排除只能用在單元列 ","")&IF(AND(L4="Y",B4<>"",SUMPRODUCT(($A$2:$A$500=A4)*($C$2:$C$500=C4)*($B$2:$B$500=""))=0),"⚠ 排除需對應共用項次 ","")&IF(AND(L4<>"Y",OR(D4="",E4="",G4="")),"⚠ 必填未填 ","")&IF(AND(L4<>"Y",D4<>"",COUNTIF(表單!$A$2:$A$500,A4)>0,NOT(ISNUMBER(SEARCH("、"&D4&"、","、"&IFERROR(INDEX(表單!$J$2:$J$500,MATCH(A4,表單!$A$2:$A$500,0)),"")&"、")))),"⚠ 階段不在此表單的階段設定內 ","")&IF(AND(L4<>"Y",G4="數值",N4=0),"⚠ 數值需設定欄位 ","")&IF(AND(L4<>"Y",G4="連結表單",K4=""),"⚠ 缺連結表號 ","")&IF(AND(K4<>"",COUNTIF(可連結表單!$J$2:$J$501,K4)=0),"⚠ 連結表號不存在（需為本分項的自主檢查表） ",""))="","✓",TRIM(IF(COUNTIF(表單!$A$2:$A$500,A4)=0,"⚠ 表號不存在 ","")&IF(SUMPRODUCT(($A$2:$A$500=A4)*($B$2:$B$500=B4)*($C$2:$C$500=C4))>1,"⚠ 項次重複 ","")&IF(AND(B4<>"",COUNTIF(表單!$A$2:$A$500,A4)>0,NOT(ISNUMBER(SEARCH("、"&B4&"、","、"&IFERROR(INDEX(表單!$I$2:$I$500,MATCH(A4,表單!$A$2:$A$500,0)),"")&"、")))),"⚠ 單元不在適用單元內 ","")&IF(AND(L4="Y",B4=""),"⚠ 排除只能用在單元列 ","")&IF(AND(L4="Y",B4<>"",SUMPRODUCT(($A$2:$A$500=A4)*($C$2:$C$500=C4)*($B$2:$B$500=""))=0),"⚠ 排除需對應共用項次 ","")&IF(AND(L4<>"Y",OR(D4="",E4="",G4="")),"⚠ 必填未填 ","")&IF(AND(L4<>"Y",D4<>"",COUNTIF(表單!$A$2:$A$500,A4)>0,NOT(ISNUMBER(SEARCH("、"&D4&"、","、"&IFERROR(INDEX(表單!$J$2:$J$500,MATCH(A4,表單!$A$2:$A$500,0)),"")&"、")))),"⚠ 階段不在此表單的階段設定內 ","")&IF(AND(L4<>"Y",G4="數值",N4=0),"⚠ 數值需設定欄位 ","")&IF(AND(L4<>"Y",G4="連結表單",K4=""),"⚠ 缺連結表號 ","")&IF(AND(K4<>"",COUNTIF(可連結表單!$J$2:$J$501,K4)=0),"⚠ 連結表號不存在（需為本分項的自主檢查表） ",""))))
M5: =IF(A5="","",IF(B5="","共用",IF(L5="Y","排除（"&B5&"）",IF(SUMPRODUCT(($A$2:$A$500=A5)*($C$2:$C$500=C5)*($B$2:$B$500=""))>0,"覆蓋共用（"&B5&"）","單元新增（"&B5&"）")))) | N5: =IF(A5="","",COUNTIFS(數值欄位!$A$2:$A$500,A5,數值欄位!$C$2:$C$500,C5)) | O5: =IF(A5="","",IF(TRIM(IF(COUNTIF(表單!$A$2:$A$500,A5)=0,"⚠ 表號不存在 ","")&IF(SUMPRODUCT(($A$2:$A$500=A5)*($B$2:$B$500=B5)*($C$2:$C$500=C5))>1,"⚠ 項次重複 ","")&IF(AND(B5<>"",COUNTIF(表單!$A$2:$A$500,A5)>0,NOT(ISNUMBER(SEARCH("、"&B5&"、","、"&IFERROR(INDEX(表單!$I$2:$I$500,MATCH(A5,表單!$A$2:$A$500,0)),"")&"、")))),"⚠ 單元不在適用單元內 ","")&IF(AND(L5="Y",B5=""),"⚠ 排除只能用在單元列 ","")&IF(AND(L5="Y",B5<>"",SUMPRODUCT(($A$2:$A$500=A5)*($C$2:$C$500=C5)*($B$2:$B$500=""))=0),"⚠ 排除需對應共用項次 ","")&IF(AND(L5<>"Y",OR(D5="",E5="",G5="")),"⚠ 必填未填 ","")&IF(AND(L5<>"Y",D5<>"",COUNTIF(表單!$A$2:$A$500,A5)>0,NOT(ISNUMBER(SEARCH("、"&D5&"、","、"&IFERROR(INDEX(表單!$J$2:$J$500,MATCH(A5,表單!$A$2:$A$500,0)),"")&"、")))),"⚠ 階段不在此表單的階段設定內 ","")&IF(AND(L5<>"Y",G5="數值",N5=0),"⚠ 數值需設定欄位 ","")&IF(AND(L5<>"Y",G5="連結表單",K5=""),"⚠ 缺連結表號 ","")&IF(AND(K5<>"",COUNTIF(可連結表單!$J$2:$J$501,K5)=0),"⚠ 連結表號不存在（需為本分項的自主檢查表） ",""))="","✓",TRIM(IF(COUNTIF(表單!$A$2:$A$500,A5)=0,"⚠ 表號不存在 ","")&IF(SUMPRODUCT(($A$2:$A$500=A5)*($B$2:$B$500=B5)*($C$2:$C$500=C5))>1,"⚠ 項次重複 ","")&IF(AND(B5<>"",COUNTIF(表單!$A$2:$A$500,A5)>0,NOT(ISNUMBER(SEARCH("、"&B5&"、","、"&IFERROR(INDEX(表單!$I$2:$I$500,MATCH(A5,表單!$A$2:$A$500,0)),"")&"、")))),"⚠ 單元不在適用單元內 ","")&IF(AND(L5="Y",B5=""),"⚠ 排除只能用在單元列 ","")&IF(AND(L5="Y",B5<>"",SUMPRODUCT(($A$2:$A$500=A5)*($C$2:$C$500=C5)*($B$2:$B$500=""))=0),"⚠ 排除需對應共用項次 ","")&IF(AND(L5<>"Y",OR(D5="",E5="",G5="")),"⚠ 必填未填 ","")&IF(AND(L5<>"Y",D5<>"",COUNTIF(表單!$A$2:$A$500,A5)>0,NOT(ISNUMBER(SEARCH("、"&D5&"、","、"&IFERROR(INDEX(表單!$J$2:$J$500,MATCH(A5,表單!$A$2:$A$500,0)),"")&"、")))),"⚠ 階段不在此表單的階段設定內 ","")&IF(AND(L5<>"Y",G5="數值",N5=0),"⚠ 數值需設定欄位 ","")&IF(AND(L5<>"Y",G5="連結表單",K5=""),"⚠ 缺連結表號 ","")&IF(AND(K5<>"",COUNTIF(可連結表單!$J$2:$J$501,K5)=0),"⚠ 連結表號不存在（需為本分項的自主檢查表） ",""))))
M6: =IF(A6="","",IF(B6="","共用",IF(L6="Y","排除（"&B6&"）",IF(SUMPRODUCT(($A$2:$A$500=A6)*($C$2:$C$500=C6)*($B$2:$B$500=""))>0,"覆蓋共用（"&B6&"）","單元新增（"&B6&"）")))) | N6: =IF(A6="","",COUNTIFS(數值欄位!$A$2:$A$500,A6,數值欄位!$C$2:$C$500,C6)) | O6: =IF(A6="","",IF(TRIM(IF(COUNTIF(表單!$A$2:$A$500,A6)=0,"⚠ 表號不存在 ","")&IF(SUMPRODUCT(($A$2:$A$500=A6)*($B$2:$B$500=B6)*($C$2:$C$500=C6))>1,"⚠ 項次重複 ","")&IF(AND(B6<>"",COUNTIF(表單!$A$2:$A$500,A6)>0,NOT(ISNUMBER(SEARCH("、"&B6&"、","、"&IFERROR(INDEX(表單!$I$2:$I$500,MATCH(A6,表單!$A$2:$A$500,0)),"")&"、")))),"⚠ 單元不在適用單元內 ","")&IF(AND(L6="Y",B6=""),"⚠ 排除只能用在單元列 ","")&IF(AND(L6="Y",B6<>"",SUMPRODUCT(($A$2:$A$500=A6)*($C$2:$C$500=C6)*($B$2:$B$500=""))=0),"⚠ 排除需對應共用項次 ","")&IF(AND(L6<>"Y",OR(D6="",E6="",G6="")),"⚠ 必填未填 ","")&IF(AND(L6<>"Y",D6<>"",COUNTIF(表單!$A$2:$A$500,A6)>0,NOT(ISNUMBER(SEARCH("、"&D6&"、","、"&IFERROR(INDEX(表單!$J$2:$J$500,MATCH(A6,表單!$A$2:$A$500,0)),"")&"、")))),"⚠ 階段不在此表單的階段設定內 ","")&IF(AND(L6<>"Y",G6="數值",N6=0),"⚠ 數值需設定欄位 ","")&IF(AND(L6<>"Y",G6="連結表單",K6=""),"⚠ 缺連結表號 ","")&IF(AND(K6<>"",COUNTIF(可連結表單!$J$2:$J$501,K6)=0),"⚠ 連結表號不存在（需為本分項的自主檢查表） ",""))="","✓",TRIM(IF(COUNTIF(表單!$A$2:$A$500,A6)=0,"⚠ 表號不存在 ","")&IF(SUMPRODUCT(($A$2:$A$500=A6)*($B$2:$B$500=B6)*($C$2:$C$500=C6))>1,"⚠ 項次重複 ","")&IF(AND(B6<>"",COUNTIF(表單!$A$2:$A$500,A6)>0,NOT(ISNUMBER(SEARCH("、"&B6&"、","、"&IFERROR(INDEX(表單!$I$2:$I$500,MATCH(A6,表單!$A$2:$A$500,0)),"")&"、")))),"⚠ 單元不在適用單元內 ","")&IF(AND(L6="Y",B6=""),"⚠ 排除只能用在單元列 ","")&IF(AND(L6="Y",B6<>"",SUMPRODUCT(($A$2:$A$500=A6)*($C$2:$C$500=C6)*($B$2:$B$500=""))=0),"⚠ 排除需對應共用項次 ","")&IF(AND(L6<>"Y",OR(D6="",E6="",G6="")),"⚠ 必填未填 ","")&IF(AND(L6<>"Y",D6<>"",COUNTIF(表單!$A$2:$A$500,A6)>0,NOT(ISNUMBER(SEARCH("、"&D6&"、","、"&IFERROR(INDEX(表單!$J$2:$J$500,MATCH(A6,表單!$A$2:$A$500,0)),"")&"、")))),"⚠ 階段不在此表單的階段設定內 ","")&IF(AND(L6<>"Y",G6="數值",N6=0),"⚠ 數值需設定欄位 ","")&IF(AND(L6<>"Y",G6="連結表單",K6=""),"⚠ 缺連結表號 ","")&IF(AND(K6<>"",COUNTIF(可連結表單!$J$2:$J$501,K6)=0),"⚠ 連結表號不存在（需為本分項的自主檢查表） ",""))))
M7: =IF(A7="","",IF(B7="","共用",IF(L7="Y","排除（"&B7&"）",IF(SUMPRODUCT(($A$2:$A$500=A7)*($C$2:$C$500=C7)*($B$2:$B$500=""))>0,"覆蓋共用（"&B7&"）","單元新增（"&B7&"）")))) | N7: =IF(A7="","",COUNTIFS(數值欄位!$A$2:$A$500,A7,數值欄位!$C$2:$C$500,C7)) | O7: =IF(A7="","",IF(TRIM(IF(COUNTIF(表單!$A$2:$A$500,A7)=0,"⚠ 表號不存在 ","")&IF(SUMPRODUCT(($A$2:$A$500=A7)*($B$2:$B$500=B7)*($C$2:$C$500=C7))>1,"⚠ 項次重複 ","")&IF(AND(B7<>"",COUNTIF(表單!$A$2:$A$500,A7)>0,NOT(ISNUMBER(SEARCH("、"&B7&"、","、"&IFERROR(INDEX(表單!$I$2:$I$500,MATCH(A7,表單!$A$2:$A$500,0)),"")&"、")))),"⚠ 單元不在適用單元內 ","")&IF(AND(L7="Y",B7=""),"⚠ 排除只能用在單元列 ","")&IF(AND(L7="Y",B7<>"",SUMPRODUCT(($A$2:$A$500=A7)*($C$2:$C$500=C7)*($B$2:$B$500=""))=0),"⚠ 排除需對應共用項次 ","")&IF(AND(L7<>"Y",OR(D7="",E7="",G7="")),"⚠ 必填未填 ","")&IF(AND(L7<>"Y",D7<>"",COUNTIF(表單!$A$2:$A$500,A7)>0,NOT(ISNUMBER(SEARCH("、"&D7&"、","、"&IFERROR(INDEX(表單!$J$2:$J$500,MATCH(A7,表單!$A$2:$A$500,0)),"")&"、")))),"⚠ 階段不在此表單的階段設定內 ","")&IF(AND(L7<>"Y",G7="數值",N7=0),"⚠ 數值需設定欄位 ","")&IF(AND(L7<>"Y",G7="連結表單",K7=""),"⚠ 缺連結表號 ","")&IF(AND(K7<>"",COUNTIF(可連結表單!$J$2:$J$501,K7)=0),"⚠ 連結表號不存在（需為本分項的自主檢查表） ",""))="","✓",TRIM(IF(COUNTIF(表單!$A$2:$A$500,A7)=0,"⚠ 表號不存在 ","")&IF(SUMPRODUCT(($A$2:$A$500=A7)*($B$2:$B$500=B7)*($C$2:$C$500=C7))>1,"⚠ 項次重複 ","")&IF(AND(B7<>"",COUNTIF(表單!$A$2:$A$500,A7)>0,NOT(ISNUMBER(SEARCH("、"&B7&"、","、"&IFERROR(INDEX(表單!$I$2:$I$500,MATCH(A7,表單!$A$2:$A$500,0)),"")&"、")))),"⚠ 單元不在適用單元內 ","")&IF(AND(L7="Y",B7=""),"⚠ 排除只能用在單元列 ","")&IF(AND(L7="Y",B7<>"",SUMPRODUCT(($A$2:$A$500=A7)*($C$2:$C$500=C7)*($B$2:$B$500=""))=0),"⚠ 排除需對應共用項次 ","")&IF(AND(L7<>"Y",OR(D7="",E7="",G7="")),"⚠ 必填未填 ","")&IF(AND(L7<>"Y",D7<>"",COUNTIF(表單!$A$2:$A$500,A7)>0,NOT(ISNUMBER(SEARCH("、"&D7&"、","、"&IFERROR(INDEX(表單!$J$2:$J$500,MATCH(A7,表單!$A$2:$A$500,0)),"")&"、")))),"⚠ 階段不在此表單的階段設定內 ","")&IF(AND(L7<>"Y",G7="數值",N7=0),"⚠ 數值需設定欄位 ","")&IF(AND(L7<>"Y",G7="連結表單",K7=""),"⚠ 缺連結表號 ","")&IF(AND(K7<>"",COUNTIF(可連結表單!$J$2:$J$501,K7)=0),"⚠ 連結表號不存在（需為本分項的自主檢查表） ",""))))
M8: =IF(A8="","",IF(B8="","共用",IF(L8="Y","排除（"&B8&"）",IF(SUMPRODUCT(($A$2:$A$500=A8)*($C$2:$C$500=C8)*($B$2:$B$500=""))>0,"覆蓋共用（"&B8&"）","單元新增（"&B8&"）")))) | N8: =IF(A8="","",COUNTIFS(數值欄位!$A$2:$A$500,A8,數值欄位!$C$2:$C$500,C8)) | O8: =IF(A8="","",IF(TRIM(IF(COUNTIF(表單!$A$2:$A$500,A8)=0,"⚠ 表號不存在 ","")&IF(SUMPRODUCT(($A$2:$A$500=A8)*($B$2:$B$500=B8)*($C$2:$C$500=C8))>1,"⚠ 項次重複 ","")&IF(AND(B8<>"",COUNTIF(表單!$A$2:$A$500,A8)>0,NOT(ISNUMBER(SEARCH("、"&B8&"、","、"&IFERROR(INDEX(表單!$I$2:$I$500,MATCH(A8,表單!$A$2:$A$500,0)),"")&"、")))),"⚠ 單元不在適用單元內 ","")&IF(AND(L8="Y",B8=""),"⚠ 排除只能用在單元列 ","")&IF(AND(L8="Y",B8<>"",SUMPRODUCT(($A$2:$A$500=A8)*($C$2:$C$500=C8)*($B$2:$B$500=""))=0),"⚠ 排除需對應共用項次 ","")&IF(AND(L8<>"Y",OR(D8="",E8="",G8="")),"⚠ 必填未填 ","")&IF(AND(L8<>"Y",D8<>"",COUNTIF(表單!$A$2:$A$500,A8)>0,NOT(ISNUMBER(SEARCH("、"&D8&"、","、"&IFERROR(INDEX(表單!$J$2:$J$500,MATCH(A8,表單!$A$2:$A$500,0)),"")&"、")))),"⚠ 階段不在此表單的階段設定內 ","")&IF(AND(L8<>"Y",G8="數值",N8=0),"⚠ 數值需設定欄位 ","")&IF(AND(L8<>"Y",G8="連結表單",K8=""),"⚠ 缺連結表號 ","")&IF(AND(K8<>"",COUNTIF(可連結表單!$J$2:$J$501,K8)=0),"⚠ 連結表號不存在（需為本分項的自主檢查表） ",""))="","✓",TRIM(IF(COUNTIF(表單!$A$2:$A$500,A8)=0,"⚠ 表號不存在 ","")&IF(SUMPRODUCT(($A$2:$A$500=A8)*($B$2:$B$500=B8)*($C$2:$C$500=C8))>1,"⚠ 項次重複 ","")&IF(AND(B8<>"",COUNTIF(表單!$A$2:$A$500,A8)>0,NOT(ISNUMBER(SEARCH("、"&B8&"、","、"&IFERROR(INDEX(表單!$I$2:$I$500,MATCH(A8,表單!$A$2:$A$500,0)),"")&"、")))),"⚠ 單元不在適用單元內 ","")&IF(AND(L8="Y",B8=""),"⚠ 排除只能用在單元列 ","")&IF(AND(L8="Y",B8<>"",SUMPRODUCT(($A$2:$A$500=A8)*($C$2:$C$500=C8)*($B$2:$B$500=""))=0),"⚠ 排除需對應共用項次 ","")&IF(AND(L8<>"Y",OR(D8="",E8="",G8="")),"⚠ 必填未填 ","")&IF(AND(L8<>"Y",D8<>"",COUNTIF(表單!$A$2:$A$500,A8)>0,NOT(ISNUMBER(SEARCH("、"&D8&"、","、"&IFERROR(INDEX(表單!$J$2:$J$500,MATCH(A8,表單!$A$2:$A$500,0)),"")&"、")))),"⚠ 階段不在此表單的階段設定內 ","")&IF(AND(L8<>"Y",G8="數值",N8=0),"⚠ 數值需設定欄位 ","")&IF(AND(L8<>"Y",G8="連結表單",K8=""),"⚠ 缺連結表號 ","")&IF(AND(K8<>"",COUNTIF(可連結表單!$J$2:$J$501,K8)=0),"⚠ 連結表號不存在（需為本分項的自主檢查表） ",""))))
M9: =IF(A9="","",IF(B9="","共用",IF(L9="Y","排除（"&B9&"）",IF(SUMPRODUCT(($A$2:$A$500=A9)*($C$2:$C$500=C9)*($B$2:$B$500=""))>0,"覆蓋共用（"&B9&"）","單元新增（"&B9&"）")))) | N9: =IF(A9="","",COUNTIFS(數值欄位!$A$2:$A$500,A9,數值欄位!$C$2:$C$500,C9)) | O9: =IF(A9="","",IF(TRIM(IF(COUNTIF(表單!$A$2:$A$500,A9)=0,"⚠ 表號不存在 ","")&IF(SUMPRODUCT(($A$2:$A$500=A9)*($B$2:$B$500=B9)*($C$2:$C$500=C9))>1,"⚠ 項次重複 ","")&IF(AND(B9<>"",COUNTIF(表單!$A$2:$A$500,A9)>0,NOT(ISNUMBER(SEARCH("、"&B9&"、","、"&IFERROR(INDEX(表單!$I$2:$I$500,MATCH(A9,表單!$A$2:$A$500,0)),"")&"、")))),"⚠ 單元不在適用單元內 ","")&IF(AND(L9="Y",B9=""),"⚠ 排除只能用在單元列 ","")&IF(AND(L9="Y",B9<>"",SUMPRODUCT(($A$2:$A$500=A9)*($C$2:$C$500=C9)*($B$2:$B$500=""))=0),"⚠ 排除需對應共用項次 ","")&IF(AND(L9<>"Y",OR(D9="",E9="",G9="")),"⚠ 必填未填 ","")&IF(AND(L9<>"Y",D9<>"",COUNTIF(表單!$A$2:$A$500,A9)>0,NOT(ISNUMBER(SEARCH("、"&D9&"、","、"&IFERROR(INDEX(表單!$J$2:$J$500,MATCH(A9,表單!$A$2:$A$500,0)),"")&"、")))),"⚠ 階段不在此表單的階段設定內 ","")&IF(AND(L9<>"Y",G9="數值",N9=0),"⚠ 數值需設定欄位 ","")&IF(AND(L9<>"Y",G9="連結表單",K9=""),"⚠ 缺連結表號 ","")&IF(AND(K9<>"",COUNTIF(可連結表單!$J$2:$J$501,K9)=0),"⚠ 連結表號不存在（需為本分項的自主檢查表） ",""))="","✓",TRIM(IF(COUNTIF(表單!$A$2:$A$500,A9)=0,"⚠ 表號不存在 ","")&IF(SUMPRODUCT(($A$2:$A$500=A9)*($B$2:$B$500=B9)*($C$2:$C$500=C9))>1,"⚠ 項次重複 ","")&IF(AND(B9<>"",COUNTIF(表單!$A$2:$A$500,A9)>0,NOT(ISNUMBER(SEARCH("、"&B9&"、","、"&IFERROR(INDEX(表單!$I$2:$I$500,MATCH(A9,表單!$A$2:$A$500,0)),"")&"、")))),"⚠ 單元不在適用單元內 ","")&IF(AND(L9="Y",B9=""),"⚠ 排除只能用在單元列 ","")&IF(AND(L9="Y",B9<>"",SUMPRODUCT(($A$2:$A$500=A9)*($C$2:$C$500=C9)*($B$2:$B$500=""))=0),"⚠ 排除需對應共用項次 ","")&IF(AND(L9<>"Y",OR(D9="",E9="",G9="")),"⚠ 必填未填 ","")&IF(AND(L9<>"Y",D9<>"",COUNTIF(表單!$A$2:$A$500,A9)>0,NOT(ISNUMBER(SEARCH("、"&D9&"、","、"&IFERROR(INDEX(表單!$J$2:$J$500,MATCH(A9,表單!$A$2:$A$500,0)),"")&"、")))),"⚠ 階段不在此表單的階段設定內 ","")&IF(AND(L9<>"Y",G9="數值",N9=0),"⚠ 數值需設定欄位 ","")&IF(AND(L9<>"Y",G9="連結表單",K9=""),"⚠ 缺連結表號 ","")&IF(AND(K9<>"",COUNTIF(可連結表單!$J$2:$J$501,K9)=0),"⚠ 連結表號不存在（需為本分項的自主檢查表） ",""))))
M10: =IF(A10="","",IF(B10="","共用",IF(L10="Y","排除（"&B10&"）",IF(SUMPRODUCT(($A$2:$A$500=A10)*($C$2:$C$500=C10)*($B$2:$B$500=""))>0,"覆蓋共用（"&B10&"）","單元新增（"&B10&"）")))) | N10: =IF(A10="","",COUNTIFS(數值欄位!$A$2:$A$500,A10,數值欄位!$C$2:$C$500,C10)) | O10: =IF(A10="","",IF(TRIM(IF(COUNTIF(表單!$A$2:$A$500,A10)=0,"⚠ 表號不存在 ","")&IF(SUMPRODUCT(($A$2:$A$500=A10)*($B$2:$B$500=B10)*($C$2:$C$500=C10))>1,"⚠ 項次重複 ","")&IF(AND(B10<>"",COUNTIF(表單!$A$2:$A$500,A10)>0,NOT(ISNUMBER(SEARCH("、"&B10&"、","、"&IFERROR(INDEX(表單!$I$2:$I$500,MATCH(A10,表單!$A$2:$A$500,0)),"")&"、")))),"⚠ 單元不在適用單元內 ","")&IF(AND(L10="Y",B10=""),"⚠ 排除只能用在單元列 ","")&IF(AND(L10="Y",B10<>"",SUMPRODUCT(($A$2:$A$500=A10)*($C$2:$C$500=C10)*($B$2:$B$500=""))=0),"⚠ 排除需對應共用項次 ","")&IF(AND(L10<>"Y",OR(D10="",E10="",G10="")),"⚠ 必填未填 ","")&IF(AND(L10<>"Y",D10<>"",COUNTIF(表單!$A$2:$A$500,A10)>0,NOT(ISNUMBER(SEARCH("、"&D10&"、","、"&IFERROR(INDEX(表單!$J$2:$J$500,MATCH(A10,表單!$A$2:$A$500,0)),"")&"、")))),"⚠ 階段不在此表單的階段設定內 ","")&IF(AND(L10<>"Y",G10="數值",N10=0),"⚠ 數值需設定欄位 ","")&IF(AND(L10<>"Y",G10="連結表單",K10=""),"⚠ 缺連結表號 ","")&IF(AND(K10<>"",COUNTIF(可連結表單!$J$2:$J$501,K10)=0),"⚠ 連結表號不存在（需為本分項的自主檢查表） ",""))="","✓",TRIM(IF(COUNTIF(表單!$A$2:$A$500,A10)=0,"⚠ 表號不存在 ","")&IF(SUMPRODUCT(($A$2:$A$500=A10)*($B$2:$B$500=B10)*($C$2:$C$500=C10))>1,"⚠ 項次重複 ","")&IF(AND(B10<>"",COUNTIF(表單!$A$2:$A$500,A10)>0,NOT(ISNUMBER(SEARCH("、"&B10&"、","、"&IFERROR(INDEX(表單!$I$2:$I$500,MATCH(A10,表單!$A$2:$A$500,0)),"")&"、")))),"⚠ 單元不在適用單元內 ","")&IF(AND(L10="Y",B10=""),"⚠ 排除只能用在單元列 ","")&IF(AND(L10="Y",B10<>"",SUMPRODUCT(($A$2:$A$500=A10)*($C$2:$C$500=C10)*($B$2:$B$500=""))=0),"⚠ 排除需對應共用項次 ","")&IF(AND(L10<>"Y",OR(D10="",E10="",G10="")),"⚠ 必填未填 ","")&IF(AND(L10<>"Y",D10<>"",COUNTIF(表單!$A$2:$A$500,A10)>0,NOT(ISNUMBER(SEARCH("、"&D10&"、","、"&IFERROR(INDEX(表單!$J$2:$J$500,MATCH(A10,表單!$A$2:$A$500,0)),"")&"、")))),"⚠ 階段不在此表單的階段設定內 ","")&IF(AND(L10<>"Y",G10="數值",N10=0),"⚠ 數值需設定欄位 ","")&IF(AND(L10<>"Y",G10="連結表單",K10=""),"⚠ 缺連結表號 ","")&IF(AND(K10<>"",COUNTIF(可連結表單!$J$2:$J$501,K10)=0),"⚠ 連結表號不存在（需為本分項的自主檢查表） ",""))))
M11: =IF(A11="","",IF(B11="","共用",IF(L11="Y","排除（"&B11&"）",IF(SUMPRODUCT(($A$2:$A$500=A11)*($C$2:$C$500=C11)*($B$2:$B$500=""))>0,"覆蓋共用（"&B11&"）","單元新增（"&B11&"）")))) | N11: =IF(A11="","",COUNTIFS(數值欄位!$A$2:$A$500,A11,數值欄位!$C$2:$C$500,C11)) | O11: =IF(A11="","",IF(TRIM(IF(COUNTIF(表單!$A$2:$A$500,A11)=0,"⚠ 表號不存在 ","")&IF(SUMPRODUCT(($A$2:$A$500=A11)*($B$2:$B$500=B11)*($C$2:$C$500=C11))>1,"⚠ 項次重複 ","")&IF(AND(B11<>"",COUNTIF(表單!$A$2:$A$500,A11)>0,NOT(ISNUMBER(SEARCH("、"&B11&"、","、"&IFERROR(INDEX(表單!$I$2:$I$500,MATCH(A11,表單!$A$2:$A$500,0)),"")&"、")))),"⚠ 單元不在適用單元內 ","")&IF(AND(L11="Y",B11=""),"⚠ 排除只能用在單元列 ","")&IF(AND(L11="Y",B11<>"",SUMPRODUCT(($A$2:$A$500=A11)*($C$2:$C$500=C11)*($B$2:$B$500=""))=0),"⚠ 排除需對應共用項次 ","")&IF(AND(L11<>"Y",OR(D11="",E11="",G11="")),"⚠ 必填未填 ","")&IF(AND(L11<>"Y",D11<>"",COUNTIF(表單!$A$2:$A$500,A11)>0,NOT(ISNUMBER(SEARCH("、"&D11&"、","、"&IFERROR(INDEX(表單!$J$2:$J$500,MATCH(A11,表單!$A$2:$A$500,0)),"")&"、")))),"⚠ 階段不在此表單的階段設定內 ","")&IF(AND(L11<>"Y",G11="數值",N11=0),"⚠ 數值需設定欄位 ","")&IF(AND(L11<>"Y",G11="連結表單",K11=""),"⚠ 缺連結表號 ","")&IF(AND(K11<>"",COUNTIF(可連結表單!$J$2:$J$501,K11)=0),"⚠ 連結表號不存在（需為本分項的自主檢查表） ",""))="","✓",TRIM(IF(COUNTIF(表單!$A$2:$A$500,A11)=0,"⚠ 表號不存在 ","")&IF(SUMPRODUCT(($A$2:$A$500=A11)*($B$2:$B$500=B11)*($C$2:$C$500=C11))>1,"⚠ 項次重複 ","")&IF(AND(B11<>"",COUNTIF(表單!$A$2:$A$500,A11)>0,NOT(ISNUMBER(SEARCH("、"&B11&"、","、"&IFERROR(INDEX(表單!$I$2:$I$500,MATCH(A11,表單!$A$2:$A$500,0)),"")&"、")))),"⚠ 單元不在適用單元內 ","")&IF(AND(L11="Y",B11=""),"⚠ 排除只能用在單元列 ","")&IF(AND(L11="Y",B11<>"",SUMPRODUCT(($A$2:$A$500=A11)*($C$2:$C$500=C11)*($B$2:$B$500=""))=0),"⚠ 排除需對應共用項次 ","")&IF(AND(L11<>"Y",OR(D11="",E11="",G11="")),"⚠ 必填未填 ","")&IF(AND(L11<>"Y",D11<>"",COUNTIF(表單!$A$2:$A$500,A11)>0,NOT(ISNUMBER(SEARCH("、"&D11&"、","、"&IFERROR(INDEX(表單!$J$2:$J$500,MATCH(A11,表單!$A$2:$A$500,0)),"")&"、")))),"⚠ 階段不在此表單的階段設定內 ","")&IF(AND(L11<>"Y",G11="數值",N11=0),"⚠ 數值需設定欄位 ","")&IF(AND(L11<>"Y",G11="連結表單",K11=""),"⚠ 缺連結表號 ","")&IF(AND(K11<>"",COUNTIF(可連結表單!$J$2:$J$501,K11)=0),"⚠ 連結表號不存在（需為本分項的自主檢查表） ",""))))
M12: =IF(A12="","",IF(B12="","共用",IF(L12="Y","排除（"&B12&"）",IF(SUMPRODUCT(($A$2:$A$500=A12)*($C$2:$C$500=C12)*($B$2:$B$500=""))>0,"覆蓋共用（"&B12&"）","單元新增（"&B12&"）")))) | N12: =IF(A12="","",COUNTIFS(數值欄位!$A$2:$A$500,A12,數值欄位!$C$2:$C$500,C12)) | O12: =IF(A12="","",IF(TRIM(IF(COUNTIF(表單!$A$2:$A$500,A12)=0,"⚠ 表號不存在 ","")&IF(SUMPRODUCT(($A$2:$A$500=A12)*($B$2:$B$500=B12)*($C$2:$C$500=C12))>1,"⚠ 項次重複 ","")&IF(AND(B12<>"",COUNTIF(表單!$A$2:$A$500,A12)>0,NOT(ISNUMBER(SEARCH("、"&B12&"、","、"&IFERROR(INDEX(表單!$I$2:$I$500,MATCH(A12,表單!$A$2:$A$500,0)),"")&"、")))),"⚠ 單元不在適用單元內 ","")&IF(AND(L12="Y",B12=""),"⚠ 排除只能用在單元列 ","")&IF(AND(L12="Y",B12<>"",SUMPRODUCT(($A$2:$A$500=A12)*($C$2:$C$500=C12)*($B$2:$B$500=""))=0),"⚠ 排除需對應共用項次 ","")&IF(AND(L12<>"Y",OR(D12="",E12="",G12="")),"⚠ 必填未填 ","")&IF(AND(L12<>"Y",D12<>"",COUNTIF(表單!$A$2:$A$500,A12)>0,NOT(ISNUMBER(SEARCH("、"&D12&"、","、"&IFERROR(INDEX(表單!$J$2:$J$500,MATCH(A12,表單!$A$2:$A$500,0)),"")&"、")))),"⚠ 階段不在此表單的階段設定內 ","")&IF(AND(L12<>"Y",G12="數值",N12=0),"⚠ 數值需設定欄位 ","")&IF(AND(L12<>"Y",G12="連結表單",K12=""),"⚠ 缺連結表號 ","")&IF(AND(K12<>"",COUNTIF(可連結表單!$J$2:$J$501,K12)=0),"⚠ 連結表號不存在（需為本分項的自主檢查表） ",""))="","✓",TRIM(IF(COUNTIF(表單!$A$2:$A$500,A12)=0,"⚠ 表號不存在 ","")&IF(SUMPRODUCT(($A$2:$A$500=A12)*($B$2:$B$500=B12)*($C$2:$C$500=C12))>1,"⚠ 項次重複 ","")&IF(AND(B12<>"",COUNTIF(表單!$A$2:$A$500,A12)>0,NOT(ISNUMBER(SEARCH("、"&B12&"、","、"&IFERROR(INDEX(表單!$I$2:$I$500,MATCH(A12,表單!$A$2:$A$500,0)),"")&"、")))),"⚠ 單元不在適用單元內 ","")&IF(AND(L12="Y",B12=""),"⚠ 排除只能用在單元列 ","")&IF(AND(L12="Y",B12<>"",SUMPRODUCT(($A$2:$A$500=A12)*($C$2:$C$500=C12)*($B$2:$B$500=""))=0),"⚠ 排除需對應共用項次 ","")&IF(AND(L12<>"Y",OR(D12="",E12="",G12="")),"⚠ 必填未填 ","")&IF(AND(L12<>"Y",D12<>"",COUNTIF(表單!$A$2:$A$500,A12)>0,NOT(ISNUMBER(SEARCH("、"&D12&"、","、"&IFERROR(INDEX(表單!$J$2:$J$500,MATCH(A12,表單!$A$2:$A$500,0)),"")&"、")))),"⚠ 階段不在此表單的階段設定內 ","")&IF(AND(L12<>"Y",G12="數值",N12=0),"⚠ 數值需設定欄位 ","")&IF(AND(L12<>"Y",G12="連結表單",K12=""),"⚠ 缺連結表號 ","")&IF(AND(K12<>"",COUNTIF(可連結表單!$J$2:$J$501,K12)=0),"⚠ 連結表號不存在（需為本分項的自主檢查表） ",""))))
M13: =IF(A13="","",IF(B13="","共用",IF(L13="Y","排除（"&B13&"）",IF(SUMPRODUCT(($A$2:$A$500=A13)*($C$2:$C$500=C13)*($B$2:$B$500=""))>0,"覆蓋共用（"&B13&"）","單元新增（"&B13&"）")))) | N13: =IF(A13="","",COUNTIFS(數值欄位!$A$2:$A$500,A13,數值欄位!$C$2:$C$500,C13)) | O13: =IF(A13="","",IF(TRIM(IF(COUNTIF(表單!$A$2:$A$500,A13)=0,"⚠ 表號不存在 ","")&IF(SUMPRODUCT(($A$2:$A$500=A13)*($B$2:$B$500=B13)*($C$2:$C$500=C13))>1,"⚠ 項次重複 ","")&IF(AND(B13<>"",COUNTIF(表單!$A$2:$A$500,A13)>0,NOT(ISNUMBER(SEARCH("、"&B13&"、","、"&IFERROR(INDEX(表單!$I$2:$I$500,MATCH(A13,表單!$A$2:$A$500,0)),"")&"、")))),"⚠ 單元不在適用單元內 ","")&IF(AND(L13="Y",B13=""),"⚠ 排除只能用在單元列 ","")&IF(AND(L13="Y",B13<>"",SUMPRODUCT(($A$2:$A$500=A13)*($C$2:$C$500=C13)*($B$2:$B$500=""))=0),"⚠ 排除需對應共用項次 ","")&IF(AND(L13<>"Y",OR(D13="",E13="",G13="")),"⚠ 必填未填 ","")&IF(AND(L13<>"Y",D13<>"",COUNTIF(表單!$A$2:$A$500,A13)>0,NOT(ISNUMBER(SEARCH("、"&D13&"、","、"&IFERROR(INDEX(表單!$J$2:$J$500,MATCH(A13,表單!$A$2:$A$500,0)),"")&"、")))),"⚠ 階段不在此表單的階段設定內 ","")&IF(AND(L13<>"Y",G13="數值",N13=0),"⚠ 數值需設定欄位 ","")&IF(AND(L13<>"Y",G13="連結表單",K13=""),"⚠ 缺連結表號 ","")&IF(AND(K13<>"",COUNTIF(可連結表單!$J$2:$J$501,K13)=0),"⚠ 連結表號不存在（需為本分項的自主檢查表） ",""))="","✓",TRIM(IF(COUNTIF(表單!$A$2:$A$500,A13)=0,"⚠ 表號不存在 ","")&IF(SUMPRODUCT(($A$2:$A$500=A13)*($B$2:$B$500=B13)*($C$2:$C$500=C13))>1,"⚠ 項次重複 ","")&IF(AND(B13<>"",COUNTIF(表單!$A$2:$A$500,A13)>0,NOT(ISNUMBER(SEARCH("、"&B13&"、","、"&IFERROR(INDEX(表單!$I$2:$I$500,MATCH(A13,表單!$A$2:$A$500,0)),"")&"、")))),"⚠ 單元不在適用單元內 ","")&IF(AND(L13="Y",B13=""),"⚠ 排除只能用在單元列 ","")&IF(AND(L13="Y",B13<>"",SUMPRODUCT(($A$2:$A$500=A13)*($C$2:$C$500=C13)*($B$2:$B$500=""))=0),"⚠ 排除需對應共用項次 ","")&IF(AND(L13<>"Y",OR(D13="",E13="",G13="")),"⚠ 必填未填 ","")&IF(AND(L13<>"Y",D13<>"",COUNTIF(表單!$A$2:$A$500,A13)>0,NOT(ISNUMBER(SEARCH("、"&D13&"、","、"&IFERROR(INDEX(表單!$J$2:$J$500,MATCH(A13,表單!$A$2:$A$500,0)),"")&"、")))),"⚠ 階段不在此表單的階段設定內 ","")&IF(AND(L13<>"Y",G13="數值",N13=0),"⚠ 數值需設定欄位 ","")&IF(AND(L13<>"Y",G13="連結表單",K13=""),"⚠ 缺連結表號 ","")&IF(AND(K13<>"",COUNTIF(可連結表單!$J$2:$J$501,K13)=0),"⚠ 連結表號不存在（需為本分項的自主檢查表） ",""))))
... M300: =IF(A300="","",IF(B300="","共用",IF(L300="Y","排除（"&B300&"）",IF(SUMPRODUCT(($A$2:$A$500=A300)*($C$2:$C$500=C300)*($B$2:$B$500=""))>0,"覆蓋共用（"&B300&"）","單元新增（"&B300&"）")))) | N300: =IF(A300="","",COUNTIFS(數值欄位!$A$2:$A$500,A300,數值欄位!$C$2:$C$500,C300)) | O300: =IF(A300="","",IF(TRIM(IF(COUNTIF(表單!$A$2:$A$500,A300)=0,"⚠ 表號不存在 ","")&IF(SUMPRODUCT(($A$2:$A$500=A300)*($B$2:$B$500=B300)*($C$2:$C$500=C300))>1,"⚠ 項次重複 ","")&IF(AND(B300<>"",COUNTIF(表單!$A$2:$A$500,A300)>0,NOT(ISNUMBER(SEARCH("、"&B300&"、","、"&IFERROR(INDEX(表單!$I$2:$I$500,MATCH(A300,表單!$A$2:$A$500,0)),"")&"、")))),"⚠ 單元不在適用單元內 ","")&IF(AND(L300="Y",B300=""),"⚠ 排除只能用在單元列 ","")&IF(AND(L300="Y",B300<>"",SUMPRODUCT(($A$2:$A$500=A300)*($C$2:$C$500=C300)*($B$2:$B$500=""))=0),"⚠ 排除需對應共用項次 ","")&IF(AND(L300<>"Y",OR(D300="",E300="",G300="")),"⚠ 必填未填 ","")&IF(AND(L300<>"Y",D300<>"",COUNTIF(表單!$A$2:$A$500,A300)>0,NOT(ISNUMBER(SEARCH("、"&D300&"、","、"&IFERROR(INDEX(表單!$J$2:$J$500,MATCH(A300,表單!$A$2:$A$500,0)),"")&"、")))),"⚠ 階段不在此表單的階段設定內 ","")&IF(AND(L300<>"Y",G300="數值",N300=0),"⚠ 數值需設定欄位 ","")&IF(AND(L300<>"Y",G300="連結表單",K300=""),"⚠ 缺連結表號 ","")&IF(AND(K300<>"",COUNTIF(可連結表單!$J$2:$J$501,K300)=0),"⚠ 連結表號不存在（需為本分項的自主檢查表） ",""))="","✓",TRIM(IF(COUNTIF(表單!$A$2:$A$500,A300)=0,"⚠ 表號不存在 ","")&IF(SUMPRODUCT(($A$2:$A$500=A300)*($B$2:$B$500=B300)*($C$2:$C$500=C300))>1,"⚠ 項次重複 ","")&IF(AND(B300<>"",COUNTIF(表單!$A$2:$A$500,A300)>0,NOT(ISNUMBER(SEARCH("、"&B300&"、","、"&IFERROR(INDEX(表單!$I$2:$I$500,MATCH(A300,表單!$A$2:$A$500,0)),"")&"、")))),"⚠ 單元不在適用單元內 ","")&IF(AND(L300="Y",B300=""),"⚠ 排除只能用在單元列 ","")&IF(AND(L300="Y",B300<>"",SUMPRODUCT(($A$2:$A$500=A300)*($C$2:$C$500=C300)*($B$2:$B$500=""))=0),"⚠ 排除需對應共用項次 ","")&IF(AND(L300<>"Y",OR(D300="",E300="",G300="")),"⚠ 必填未填 ","")&IF(AND(L300<>"Y",D300<>"",COUNTIF(表單!$A$2:$A$500,A300)>0,NOT(ISNUMBER(SEARCH("、"&D300&"、","、"&IFERROR(INDEX(表單!$J$2:$J$500,MATCH(A300,表單!$A$2:$A$500,0)),"")&"、")))),"⚠ 階段不在此表單的階段設定內 ","")&IF(AND(L300<>"Y",G300="數值",N300=0),"⚠ 數值需設定欄位 ","")&IF(AND(L300<>"Y",G300="連結表單",K300=""),"⚠ 缺連結表號 ","")&IF(AND(K300<>"",COUNTIF(可連結表單!$J$2:$J$501,K300)=0),"⚠ 連結表號不存在（需為本分項的自主檢查表） ",""))))

Sheet 數值欄位
A1: 表號 * | B1: 單元編號 | C1: 項次 * | D1: 欄位名稱 * | E1: 單位 | F1: 下限 | G1: 上限 | H1: 排除 | I1: 檢查項目 | J1: 套用方式 | K1: 檢核條件 | L1: 檢查
I2: =IF(A2="","",IFERROR(INDEX(檢查項目!$E$2:$E$500,MATCH(1,INDEX((檢查項目!$A$2:$A$500=A2)*(檢查項目!$C$2:$C$500=C2)*(檢查項目!$B$2:$B$500=B2),0),0)),IFERROR(INDEX(檢查項目!$E$2:$E$500,MATCH(1,INDEX((檢查項目!$A$2:$A$500=A2)*(檢查項目!$C$2:$C$500=C2)*(檢查項目!$B$2:$B$500=""),0),0)),"⚠ 找不到項目"))) | J2: =IF(A2="","",IF(B2="","共用",IF(H2="Y","排除（"&B2&"）",IF(SUMPRODUCT(($A$2:$A$500=A2)*($C$2:$C$500=C2)*($D$2:$D$500=D2)*($B$2:$B$500=""))>0,"覆蓋共用（"&B2&"）","單元新增（"&B2&"）")))) | K2: =IF(A2="","",IF(H2="Y","—",IF(AND(F2<>"",G2<>""),F2&" ~ "&G2,IF(G2<>"","≤ "&G2,IF(F2<>"","≥ "&F2,"只記錄、不檢核"))))) | L2: =IF(A2="","",IF(TRIM(IF(SUMPRODUCT(($A$2:$A$500=A2)*($B$2:$B$500=B2)*($C$2:$C$500=C2)*($D$2:$D$500=D2))>1,"⚠ 欄位名稱重複 ","")&IF(AND(B2<>"",NOT(ISNUMBER(SEARCH("、"&B2&"、","、"&IFERROR(INDEX(表單!$I$2:$I$500,MATCH(A2,表單!$A$2:$A$500,0)),"")&"、")))),"⚠ 單元不在適用單元內 ","")&IF(AND(H2="Y",B2=""),"⚠ 排除只能用在單元列 ","")&IF(AND(H2="Y",B2<>"",SUMPRODUCT(($A$2:$A$500=A2)*($C$2:$C$500=C2)*($D$2:$D$500=D2)*($B$2:$B$500=""))=0),"⚠ 排除需對應共用欄位 ","")&IF(AND(ISNUMBER(F2),ISNUMBER(G2),F2>G2),"⚠ 下限大於上限 ","")&IF(SUMPRODUCT((檢查項目!$A$2:$A$500=A2)*(檢查項目!$C$2:$C$500=C2)*(檢查項目!$G$2:$G$500="數值"))=0,"⚠ 該項目不是數值類型 ",""))="","✓",TRIM(IF(SUMPRODUCT(($A$2:$A$500=A2)*($B$2:$B$500=B2)*($C$2:$C$500=C2)*($D$2:$D$500=D2))>1,"⚠ 欄位名稱重複 ","")&IF(AND(B2<>"",NOT(ISNUMBER(SEARCH("、"&B2&"、","、"&IFERROR(INDEX(表單!$I$2:$I$500,MATCH(A2,表單!$A$2:$A$500,0)),"")&"、")))),"⚠ 單元不在適用單元內 ","")&IF(AND(H2="Y",B2=""),"⚠ 排除只能用在單元列 ","")&IF(AND(H2="Y",B2<>"",SUMPRODUCT(($A$2:$A$500=A2)*($C$2:$C$500=C2)*($D$2:$D$500=D2)*($B$2:$B$500=""))=0),"⚠ 排除需對應共用欄位 ","")&IF(AND(ISNUMBER(F2),ISNUMBER(G2),F2>G2),"⚠ 下限大於上限 ","")&IF(SUMPRODUCT((檢查項目!$A$2:$A$500=A2)*(檢查項目!$C$2:$C$500=C2)*(檢查項目!$G$2:$G$500="數值"))=0,"⚠ 該項目不是數值類型 ",""))))
I3: =IF(A3="","",IFERROR(INDEX(檢查項目!$E$2:$E$500,MATCH(1,INDEX((檢查項目!$A$2:$A$500=A3)*(檢查項目!$C$2:$C$500=C3)*(檢查項目!$B$2:$B$500=B3),0),0)),IFERROR(INDEX(檢查項目!$E$2:$E$500,MATCH(1,INDEX((檢查項目!$A$2:$A$500=A3)*(檢查項目!$C$2:$C$500=C3)*(檢查項目!$B$2:$B$500=""),0),0)),"⚠ 找不到項目"))) | J3: =IF(A3="","",IF(B3="","共用",IF(H3="Y","排除（"&B3&"）",IF(SUMPRODUCT(($A$2:$A$500=A3)*($C$2:$C$500=C3)*($D$2:$D$500=D3)*($B$2:$B$500=""))>0,"覆蓋共用（"&B3&"）","單元新增（"&B3&"）")))) | K3: =IF(A3="","",IF(H3="Y","—",IF(AND(F3<>"",G3<>""),F3&" ~ "&G3,IF(G3<>"","≤ "&G3,IF(F3<>"","≥ "&F3,"只記錄、不檢核"))))) | L3: =IF(A3="","",IF(TRIM(IF(SUMPRODUCT(($A$2:$A$500=A3)*($B$2:$B$500=B3)*($C$2:$C$500=C3)*($D$2:$D$500=D3))>1,"⚠ 欄位名稱重複 ","")&IF(AND(B3<>"",NOT(ISNUMBER(SEARCH("、"&B3&"、","、"&IFERROR(INDEX(表單!$I$2:$I$500,MATCH(A3,表單!$A$2:$A$500,0)),"")&"、")))),"⚠ 單元不在適用單元內 ","")&IF(AND(H3="Y",B3=""),"⚠ 排除只能用在單元列 ","")&IF(AND(H3="Y",B3<>"",SUMPRODUCT(($A$2:$A$500=A3)*($C$2:$C$500=C3)*($D$2:$D$500=D3)*($B$2:$B$500=""))=0),"⚠ 排除需對應共用欄位 ","")&IF(AND(ISNUMBER(F3),ISNUMBER(G3),F3>G3),"⚠ 下限大於上限 ","")&IF(SUMPRODUCT((檢查項目!$A$2:$A$500=A3)*(檢查項目!$C$2:$C$500=C3)*(檢查項目!$G$2:$G$500="數值"))=0,"⚠ 該項目不是數值類型 ",""))="","✓",TRIM(IF(SUMPRODUCT(($A$2:$A$500=A3)*($B$2:$B$500=B3)*($C$2:$C$500=C3)*($D$2:$D$500=D3))>1,"⚠ 欄位名稱重複 ","")&IF(AND(B3<>"",NOT(ISNUMBER(SEARCH("、"&B3&"、","、"&IFERROR(INDEX(表單!$I$2:$I$500,MATCH(A3,表單!$A$2:$A$500,0)),"")&"、")))),"⚠ 單元不在適用單元內 ","")&IF(AND(H3="Y",B3=""),"⚠ 排除只能用在單元列 ","")&IF(AND(H3="Y",B3<>"",SUMPRODUCT(($A$2:$A$500=A3)*($C$2:$C$500=C3)*($D$2:$D$500=D3)*($B$2:$B$500=""))=0),"⚠ 排除需對應共用欄位 ","")&IF(AND(ISNUMBER(F3),ISNUMBER(G3),F3>G3),"⚠ 下限大於上限 ","")&IF(SUMPRODUCT((檢查項目!$A$2:$A$500=A3)*(檢查項目!$C$2:$C$500=C3)*(檢查項目!$G$2:$G$500="數值"))=0,"⚠ 該項目不是數值類型 ",""))))
I4: =IF(A4="","",IFERROR(INDEX(檢查項目!$E$2:$E$500,MATCH(1,INDEX((檢查項目!$A$2:$A$500=A4)*(檢查項目!$C$2:$C$500=C4)*(檢查項目!$B$2:$B$500=B4),0),0)),IFERROR(INDEX(檢查項目!$E$2:$E$500,MATCH(1,INDEX((檢查項目!$A$2:$A$500=A4)*(檢查項目!$C$2:$C$500=C4)*(檢查項目!$B$2:$B$500=""),0),0)),"⚠ 找不到項目"))) | J4: =IF(A4="","",IF(B4="","共用",IF(H4="Y","排除（"&B4&"）",IF(SUMPRODUCT(($A$2:$A$500=A4)*($C$2:$C$500=C4)*($D$2:$D$500=D4)*($B$2:$B$500=""))>0,"覆蓋共用（"&B4&"）","單元新增（"&B4&"）")))) | K4: =IF(A4="","",IF(H4="Y","—",IF(AND(F4<>"",G4<>""),F4&" ~ "&G4,IF(G4<>"","≤ "&G4,IF(F4<>"","≥ "&F4,"只記錄、不檢核"))))) | L4: =IF(A4="","",IF(TRIM(IF(SUMPRODUCT(($A$2:$A$500=A4)*($B$2:$B$500=B4)*($C$2:$C$500=C4)*($D$2:$D$500=D4))>1,"⚠ 欄位名稱重複 ","")&IF(AND(B4<>"",NOT(ISNUMBER(SEARCH("、"&B4&"、","、"&IFERROR(INDEX(表單!$I$2:$I$500,MATCH(A4,表單!$A$2:$A$500,0)),"")&"、")))),"⚠ 單元不在適用單元內 ","")&IF(AND(H4="Y",B4=""),"⚠ 排除只能用在單元列 ","")&IF(AND(H4="Y",B4<>"",SUMPRODUCT(($A$2:$A$500=A4)*($C$2:$C$500=C4)*($D$2:$D$500=D4)*($B$2:$B$500=""))=0),"⚠ 排除需對應共用欄位 ","")&IF(AND(ISNUMBER(F4),ISNUMBER(G4),F4>G4),"⚠ 下限大於上限 ","")&IF(SUMPRODUCT((檢查項目!$A$2:$A$500=A4)*(檢查項目!$C$2:$C$500=C4)*(檢查項目!$G$2:$G$500="數值"))=0,"⚠ 該項目不是數值類型 ",""))="","✓",TRIM(IF(SUMPRODUCT(($A$2:$A$500=A4)*($B$2:$B$500=B4)*($C$2:$C$500=C4)*($D$2:$D$500=D4))>1,"⚠ 欄位名稱重複 ","")&IF(AND(B4<>"",NOT(ISNUMBER(SEARCH("、"&B4&"、","、"&IFERROR(INDEX(表單!$I$2:$I$500,MATCH(A4,表單!$A$2:$A$500,0)),"")&"、")))),"⚠ 單元不在適用單元內 ","")&IF(AND(H4="Y",B4=""),"⚠ 排除只能用在單元列 ","")&IF(AND(H4="Y",B4<>"",SUMPRODUCT(($A$2:$A$500=A4)*($C$2:$C$500=C4)*($D$2:$D$500=D4)*($B$2:$B$500=""))=0),"⚠ 排除需對應共用欄位 ","")&IF(AND(ISNUMBER(F4),ISNUMBER(G4),F4>G4),"⚠ 下限大於上限 ","")&IF(SUMPRODUCT((檢查項目!$A$2:$A$500=A4)*(檢查項目!$C$2:$C$500=C4)*(檢查項目!$G$2:$G$500="數值"))=0,"⚠ 該項目不是數值類型 ",""))))
I5: =IF(A5="","",IFERROR(INDEX(檢查項目!$E$2:$E$500,MATCH(1,INDEX((檢查項目!$A$2:$A$500=A5)*(檢查項目!$C$2:$C$500=C5)*(檢查項目!$B$2:$B$500=B5),0),0)),IFERROR(INDEX(檢查項目!$E$2:$E$500,MATCH(1,INDEX((檢查項目!$A$2:$A$500=A5)*(檢查項目!$C$2:$C$500=C5)*(檢查項目!$B$2:$B$500=""),0),0)),"⚠ 找不到項目"))) | J5: =IF(A5="","",IF(B5="","共用",IF(H5="Y","排除（"&B5&"）",IF(SUMPRODUCT(($A$2:$A$500=A5)*($C$2:$C$500=C5)*($D$2:$D$500=D5)*($B$2:$B$500=""))>0,"覆蓋共用（"&B5&"）","單元新增（"&B5&"）")))) | K5: =IF(A5="","",IF(H5="Y","—",IF(AND(F5<>"",G5<>""),F5&" ~ "&G5,IF(G5<>"","≤ "&G5,IF(F5<>"","≥ "&F5,"只記錄、不檢核"))))) | L5: =IF(A5="","",IF(TRIM(IF(SUMPRODUCT(($A$2:$A$500=A5)*($B$2:$B$500=B5)*($C$2:$C$500=C5)*($D$2:$D$500=D5))>1,"⚠ 欄位名稱重複 ","")&IF(AND(B5<>"",NOT(ISNUMBER(SEARCH("、"&B5&"、","、"&IFERROR(INDEX(表單!$I$2:$I$500,MATCH(A5,表單!$A$2:$A$500,0)),"")&"、")))),"⚠ 單元不在適用單元內 ","")&IF(AND(H5="Y",B5=""),"⚠ 排除只能用在單元列 ","")&IF(AND(H5="Y",B5<>"",SUMPRODUCT(($A$2:$A$500=A5)*($C$2:$C$500=C5)*($D$2:$D$500=D5)*($B$2:$B$500=""))=0),"⚠ 排除需對應共用欄位 ","")&IF(AND(ISNUMBER(F5),ISNUMBER(G5),F5>G5),"⚠ 下限大於上限 ","")&IF(SUMPRODUCT((檢查項目!$A$2:$A$500=A5)*(檢查項目!$C$2:$C$500=C5)*(檢查項目!$G$2:$G$500="數值"))=0,"⚠ 該項目不是數值類型 ",""))="","✓",TRIM(IF(SUMPRODUCT(($A$2:$A$500=A5)*($B$2:$B$500=B5)*($C$2:$C$500=C5)*($D$2:$D$500=D5))>1,"⚠ 欄位名稱重複 ","")&IF(AND(B5<>"",NOT(ISNUMBER(SEARCH("、"&B5&"、","、"&IFERROR(INDEX(表單!$I$2:$I$500,MATCH(A5,表單!$A$2:$A$500,0)),"")&"、")))),"⚠ 單元不在適用單元內 ","")&IF(AND(H5="Y",B5=""),"⚠ 排除只能用在單元列 ","")&IF(AND(H5="Y",B5<>"",SUMPRODUCT(($A$2:$A$500=A5)*($C$2:$C$500=C5)*($D$2:$D$500=D5)*($B$2:$B$500=""))=0),"⚠ 排除需對應共用欄位 ","")&IF(AND(ISNUMBER(F5),ISNUMBER(G5),F5>G5),"⚠ 下限大於上限 ","")&IF(SUMPRODUCT((檢查項目!$A$2:$A$500=A5)*(檢查項目!$C$2:$C$500=C5)*(檢查項目!$G$2:$G$500="數值"))=0,"⚠ 該項目不是數值類型 ",""))))
I6: =IF(A6="","",IFERROR(INDEX(檢查項目!$E$2:$E$500,MATCH(1,INDEX((檢查項目!$A$2:$A$500=A6)*(檢查項目!$C$2:$C$500=C6)*(檢查項目!$B$2:$B$500=B6),0),0)),IFERROR(INDEX(檢查項目!$E$2:$E$500,MATCH(1,INDEX((檢查項目!$A$2:$A$500=A6)*(檢查項目!$C$2:$C$500=C6)*(檢查項目!$B$2:$B$500=""),0),0)),"⚠ 找不到項目"))) | J6: =IF(A6="","",IF(B6="","共用",IF(H6="Y","排除（"&B6&"）",IF(SUMPRODUCT(($A$2:$A$500=A6)*($C$2:$C$500=C6)*($D$2:$D$500=D6)*($B$2:$B$500=""))>0,"覆蓋共用（"&B6&"）","單元新增（"&B6&"）")))) | K6: =IF(A6="","",IF(H6="Y","—",IF(AND(F6<>"",G6<>""),F6&" ~ "&G6,IF(G6<>"","≤ "&G6,IF(F6<>"","≥ "&F6,"只記錄、不檢核"))))) | L6: =IF(A6="","",IF(TRIM(IF(SUMPRODUCT(($A$2:$A$500=A6)*($B$2:$B$500=B6)*($C$2:$C$500=C6)*($D$2:$D$500=D6))>1,"⚠ 欄位名稱重複 ","")&IF(AND(B6<>"",NOT(ISNUMBER(SEARCH("、"&B6&"、","、"&IFERROR(INDEX(表單!$I$2:$I$500,MATCH(A6,表單!$A$2:$A$500,0)),"")&"、")))),"⚠ 單元不在適用單元內 ","")&IF(AND(H6="Y",B6=""),"⚠ 排除只能用在單元列 ","")&IF(AND(H6="Y",B6<>"",SUMPRODUCT(($A$2:$A$500=A6)*($C$2:$C$500=C6)*($D$2:$D$500=D6)*($B$2:$B$500=""))=0),"⚠ 排除需對應共用欄位 ","")&IF(AND(ISNUMBER(F6),ISNUMBER(G6),F6>G6),"⚠ 下限大於上限 ","")&IF(SUMPRODUCT((檢查項目!$A$2:$A$500=A6)*(檢查項目!$C$2:$C$500=C6)*(檢查項目!$G$2:$G$500="數值"))=0,"⚠ 該項目不是數值類型 ",""))="","✓",TRIM(IF(SUMPRODUCT(($A$2:$A$500=A6)*($B$2:$B$500=B6)*($C$2:$C$500=C6)*($D$2:$D$500=D6))>1,"⚠ 欄位名稱重複 ","")&IF(AND(B6<>"",NOT(ISNUMBER(SEARCH("、"&B6&"、","、"&IFERROR(INDEX(表單!$I$2:$I$500,MATCH(A6,表單!$A$2:$A$500,0)),"")&"、")))),"⚠ 單元不在適用單元內 ","")&IF(AND(H6="Y",B6=""),"⚠ 排除只能用在單元列 ","")&IF(AND(H6="Y",B6<>"",SUMPRODUCT(($A$2:$A$500=A6)*($C$2:$C$500=C6)*($D$2:$D$500=D6)*($B$2:$B$500=""))=0),"⚠ 排除需對應共用欄位 ","")&IF(AND(ISNUMBER(F6),ISNUMBER(G6),F6>G6),"⚠ 下限大於上限 ","")&IF(SUMPRODUCT((檢查項目!$A$2:$A$500=A6)*(檢查項目!$C$2:$C$500=C6)*(檢查項目!$G$2:$G$500="數值"))=0,"⚠ 該項目不是數值類型 ",""))))
I7: =IF(A7="","",IFERROR(INDEX(檢查項目!$E$2:$E$500,MATCH(1,INDEX((檢查項目!$A$2:$A$500=A7)*(檢查項目!$C$2:$C$500=C7)*(檢查項目!$B$2:$B$500=B7),0),0)),IFERROR(INDEX(檢查項目!$E$2:$E$500,MATCH(1,INDEX((檢查項目!$A$2:$A$500=A7)*(檢查項目!$C$2:$C$500=C7)*(檢查項目!$B$2:$B$500=""),0),0)),"⚠ 找不到項目"))) | J7: =IF(A7="","",IF(B7="","共用",IF(H7="Y","排除（"&B7&"）",IF(SUMPRODUCT(($A$2:$A$500=A7)*($C$2:$C$500=C7)*($D$2:$D$500=D7)*($B$2:$B$500=""))>0,"覆蓋共用（"&B7&"）","單元新增（"&B7&"）")))) | K7: =IF(A7="","",IF(H7="Y","—",IF(AND(F7<>"",G7<>""),F7&" ~ "&G7,IF(G7<>"","≤ "&G7,IF(F7<>"","≥ "&F7,"只記錄、不檢核"))))) | L7: =IF(A7="","",IF(TRIM(IF(SUMPRODUCT(($A$2:$A$500=A7)*($B$2:$B$500=B7)*($C$2:$C$500=C7)*($D$2:$D$500=D7))>1,"⚠ 欄位名稱重複 ","")&IF(AND(B7<>"",NOT(ISNUMBER(SEARCH("、"&B7&"、","、"&IFERROR(INDEX(表單!$I$2:$I$500,MATCH(A7,表單!$A$2:$A$500,0)),"")&"、")))),"⚠ 單元不在適用單元內 ","")&IF(AND(H7="Y",B7=""),"⚠ 排除只能用在單元列 ","")&IF(AND(H7="Y",B7<>"",SUMPRODUCT(($A$2:$A$500=A7)*($C$2:$C$500=C7)*($D$2:$D$500=D7)*($B$2:$B$500=""))=0),"⚠ 排除需對應共用欄位 ","")&IF(AND(ISNUMBER(F7),ISNUMBER(G7),F7>G7),"⚠ 下限大於上限 ","")&IF(SUMPRODUCT((檢查項目!$A$2:$A$500=A7)*(檢查項目!$C$2:$C$500=C7)*(檢查項目!$G$2:$G$500="數值"))=0,"⚠ 該項目不是數值類型 ",""))="","✓",TRIM(IF(SUMPRODUCT(($A$2:$A$500=A7)*($B$2:$B$500=B7)*($C$2:$C$500=C7)*($D$2:$D$500=D7))>1,"⚠ 欄位名稱重複 ","")&IF(AND(B7<>"",NOT(ISNUMBER(SEARCH("、"&B7&"、","、"&IFERROR(INDEX(表單!$I$2:$I$500,MATCH(A7,表單!$A$2:$A$500,0)),"")&"、")))),"⚠ 單元不在適用單元內 ","")&IF(AND(H7="Y",B7=""),"⚠ 排除只能用在單元列 ","")&IF(AND(H7="Y",B7<>"",SUMPRODUCT(($A$2:$A$500=A7)*($C$2:$C$500=C7)*($D$2:$D$500=D7)*($B$2:$B$500=""))=0),"⚠ 排除需對應共用欄位 ","")&IF(AND(ISNUMBER(F7),ISNUMBER(G7),F7>G7),"⚠ 下限大於上限 ","")&IF(SUMPRODUCT((檢查項目!$A$2:$A$500=A7)*(檢查項目!$C$2:$C$500=C7)*(檢查項目!$G$2:$G$500="數值"))=0,"⚠ 該項目不是數值類型 ",""))))
I8: =IF(A8="","",IFERROR(INDEX(檢查項目!$E$2:$E$500,MATCH(1,INDEX((檢查項目!$A$2:$A$500=A8)*(檢查項目!$C$2:$C$500=C8)*(檢查項目!$B$2:$B$500=B8),0),0)),IFERROR(INDEX(檢查項目!$E$2:$E$500,MATCH(1,INDEX((檢查項目!$A$2:$A$500=A8)*(檢查項目!$C$2:$C$500=C8)*(檢查項目!$B$2:$B$500=""),0),0)),"⚠ 找不到項目"))) | J8: =IF(A8="","",IF(B8="","共用",IF(H8="Y","排除（"&B8&"）",IF(SUMPRODUCT(($A$2:$A$500=A8)*($C$2:$C$500=C8)*($D$2:$D$500=D8)*($B$2:$B$500=""))>0,"覆蓋共用（"&B8&"）","單元新增（"&B8&"）")))) | K8: =IF(A8="","",IF(H8="Y","—",IF(AND(F8<>"",G8<>""),F8&" ~ "&G8,IF(G8<>"","≤ "&G8,IF(F8<>"","≥ "&F8,"只記錄、不檢核"))))) | L8: =IF(A8="","",IF(TRIM(IF(SUMPRODUCT(($A$2:$A$500=A8)*($B$2:$B$500=B8)*($C$2:$C$500=C8)*($D$2:$D$500=D8))>1,"⚠ 欄位名稱重複 ","")&IF(AND(B8<>"",NOT(ISNUMBER(SEARCH("、"&B8&"、","、"&IFERROR(INDEX(表單!$I$2:$I$500,MATCH(A8,表單!$A$2:$A$500,0)),"")&"、")))),"⚠ 單元不在適用單元內 ","")&IF(AND(H8="Y",B8=""),"⚠ 排除只能用在單元列 ","")&IF(AND(H8="Y",B8<>"",SUMPRODUCT(($A$2:$A$500=A8)*($C$2:$C$500=C8)*($D$2:$D$500=D8)*($B$2:$B$500=""))=0),"⚠ 排除需對應共用欄位 ","")&IF(AND(ISNUMBER(F8),ISNUMBER(G8),F8>G8),"⚠ 下限大於上限 ","")&IF(SUMPRODUCT((檢查項目!$A$2:$A$500=A8)*(檢查項目!$C$2:$C$500=C8)*(檢查項目!$G$2:$G$500="數值"))=0,"⚠ 該項目不是數值類型 ",""))="","✓",TRIM(IF(SUMPRODUCT(($A$2:$A$500=A8)*($B$2:$B$500=B8)*($C$2:$C$500=C8)*($D$2:$D$500=D8))>1,"⚠ 欄位名稱重複 ","")&IF(AND(B8<>"",NOT(ISNUMBER(SEARCH("、"&B8&"、","、"&IFERROR(INDEX(表單!$I$2:$I$500,MATCH(A8,表單!$A$2:$A$500,0)),"")&"、")))),"⚠ 單元不在適用單元內 ","")&IF(AND(H8="Y",B8=""),"⚠ 排除只能用在單元列 ","")&IF(AND(H8="Y",B8<>"",SUMPRODUCT(($A$2:$A$500=A8)*($C$2:$C$500=C8)*($D$2:$D$500=D8)*($B$2:$B$500=""))=0),"⚠ 排除需對應共用欄位 ","")&IF(AND(ISNUMBER(F8),ISNUMBER(G8),F8>G8),"⚠ 下限大於上限 ","")&IF(SUMPRODUCT((檢查項目!$A$2:$A$500=A8)*(檢查項目!$C$2:$C$500=C8)*(檢查項目!$G$2:$G$500="數值"))=0,"⚠ 該項目不是數值類型 ",""))))
